Workbook

Sheet PIVOT DATA
A2: DEVICE SELECTION | B2: COUNT | C2: Column1 | D2: TOTAL COUNT
A3: UTENSIL HOLDER | B3: 70 | C3: *3 | D3: 210
A4: PALM PEN HOLDER | B4: 70 | C4: *3 | D4: =B4*3 -> 210
A5: TOOTH BRUSH HOLDER | B5: 60 | C5: *3 | D5: =B5*3 -> 180
A6: BUTTON AID | B6: 50 | D6: =B6 -> 50
A7: READING BAR | B7: 30 | C7: *2 | D7: 60
A8: ASSISTIVE PENCIL GRIP | B8: 40 | C8: *2 | D8: 80
A9: LOW PROFILE SWITCH | B9: 50 | D9: =B9 -> 50
A10: TOTAL | B10: =SUM(B3:B9) -> 370 | D10: =SUM(D3:D9) -> 840
A13: District wise Distribution
A14: DISTRICT | B14: Assistive Pencil Grip | C14: BUTTON AID | D14: LOW PROFILE SWITCH | E14: PALM PEN HOLDER | F14: READING BAR - CURVED | G14: TOOTH BRUSH ADAPTER | H14: UTENSIL HOLDER | I14: GRAND TOTAL
A15: ALAPPUZHA | B15: 4 | C15: 3 | D15: 5 | E15: 27 | F15: 6 | G15: 33 | H15: 36 | I15: 114
A16: ERNAKULAM | B16: 2 | C16: 1 | D16: 6 | E16: 21 | F16: 6 | G16: 6 | H16: 24 | I16: 66
A17: IDUKKI | C17: 1 | D17: 5 | E17: 3 | F17: 0 | G17: 3 | H17: 0 | I17: 12
A18: KANNUR | B18: 2 | C18: 2 | E18: 6 | F18: 0 | G18: 3 | H18: 6 | I18: 19
A19: KAZARGOD | C19: 5 | E19: 15 | F19: 0 | G19: 3 | H19: 3 | I19: 26
A20: KOLLAM | B20: 32 | C20: 14 | D20: 7 | E20: 45 | F20: 18 | G20: 51 | H20: 63 | I20: 230
A21: KOTTAYAM | B21: 2 | C21: 1 | D21: 3 | E21: 3 | F21: 2 | G21: 0 | H21: 6 | I21: 17
A22: KOZHIKODE | B22: 4 | C22: 1 | E22: 6 | F22: 0 | G22: 0 | H22: 0 | I22: 11
A23: MALAPPURAM | B23: 2 | C23: 6 | D23: 4 | E23: 21 | F23: 6 | G23: 27 | H23: 18 | I23: 84
A24: PALAKKAD | B24: 4 | C24: 3 | D24: 1 | E24: 12 | F24: 0 | G24: 6 | H24: 3 | I24: 29
A25: PATHANAMTHITTA | B25: 14 | C25: 3 | D25: 7 | E25: 6 | F25: 6 | G25: 9 | H25: 6 | I25: 51
A26: THRISSUR | C26: 1 | D26: 4 | E26: 6 | F26: 2 | G26: 6 | H26: 12 | I26: 31
A27: TRIVANDRUM | B27: 12 | C27: 9 | D27: 8 | E27: 30 | F27: 14 | G27: 33 | H27: 24 | I27: 130
A28: WAYANAD | B28: 2 | E28: 9 | F28: 0 | G28: 0 | H28: 9 | I28: 20
A29: Grand Total | B29: 80 | C29: 50 | D29: 50 | E29: 210 | F29: 60 | G29: 180 | H29: 210 | I29: 840
A32: BUDS SCHOOL | B32: DISTRICT | C32: STUDENT COUNT | D32: ASSISTIVE PENCIL GRIP | E32: BUTTON AID | F32: LOW PROFILE SWITCH | G32: PALM PEN HOLDER | H32: READING BAR - CURVED | I32: TOOTH BRUSH ADAPTER | J32: UTENSIL HOLDER | K32: DEVICE COUNT | L32: DC-LPS
A33: ADARSH SCHOOL | B33: ERNAKULAM | C33: 2 | D33: 0 | G33: 6 | H33: 0 | I33: 0 | J33: 0 | K33: =SUM(Table2[[#This Row],[ASSISTIVE PENCIL GRIP]:[UTENSIL HOLDER]]) -> 6 | L33: =Table2[[#This Row],[DEVICE COUNT]]-Table2[[#This Row],[LOW PROFILE SWITCH]] -> 6
A34: AGALI BUDS | B34: PALAKKAD | C34: 4 | D34: 2 | E34: 1 | F34: 1 | G34: 3 | H34: 0 | I34: 0 | J34: 0 | K34: =SUM(Table2[[#This Row],[ASSISTIVE PENCIL GRIP]:[UTENSIL HOLDER]]) -> 7 | L34: =Table2[[#This Row],[DEVICE COUNT]]-Table2[[#This Row],[LOW PROFILE SWITCH]] -> 6
A35: ANTHIKKAD BLOCK PANCHAYATH BUDS | B35: THRISSUR | C35: 9 | D35: 0 | E35: 2 | F35: 3 | G35: 3 | H35: 2 | I35: 6 | K35: =SUM(Table2[[#This Row],[ASSISTIVE PENCIL GRIP]:[UTENSIL HOLDER]]) -> 16 | L35: =Table2[[#This Row],[DEVICE COUNT]]-Table2[[#This Row],[LOW PROFILE SWITCH]] -> 13
A36: ARDRABUDS SCHOOL CHERTHALA | B36: ALAPPUZHA | C36: 6 | D36: 0 | G36: 0 | H36: 2 | I36: 9 | J36: 6 | K36: =SUM(Table2[[#This Row],[ASSISTIVE PENCIL GRIP]:[UTENSIL HOLDER]]) -> 17 | L36: =Table2[[#This Row],[DEVICE COUNT]]-Table2[[#This Row],[LOW PROFILE SWITCH]] -> 17
A37: BODHINI BUDS SCHOOL | B37: KOLLAM | C37: 15 | D37: 0 | E37: 1 | G37: 0 | H37: 2 | I37: 36 | J37: 3 | K37: =SUM(Table2[[#This Row],[ASSISTIVE PENCIL GRIP]:[UTENSIL HOLDER]]) -> 42 | L37: =Table2[[#This Row],[DEVICE COUNT]]-Table2[[#This Row],[LOW PROFILE SWITCH]] -> 42
A38: BUD SCHOOL ELOOR | B38: ERNAKULAM | C38: 1 | D38: 0 | G38: 0 | H38: 0 | I38: 0 | J38: 3 | K38: =SUM(Table2[[#This Row],[ASSISTIVE PENCIL GRIP]:[UTENSIL HOLDER]]) -> 3 | L38: =Table2[[#This Row],[DEVICE COUNT]]-Table2[[#This Row],[LOW PROFILE SWITCH]] -> 3
A39: BUDS PARADISE SPECIAL SCHOOL THRISSILERY | B39: WAYANAD | C39: 7 | D39: 2 | G39: 9 | H39: 0 | I39: 0 | J39: 9 | K39: =SUM(Table2[[#This Row],[ASSISTIVE PENCIL GRIP]:[UTENSIL HOLDER]]) -> 20 | L39: =Table2[[#This Row],[DEVICE COUNT]]-Table2[[#This Row],[LOW PROFILE SWITCH]] -> 20
A40: BUDS REHABILITATION CENTRE AKATHETHARA | B40: PALAKKAD | C40: 9 | D40: 2 | E40: 2 | G40: 9 | H40: 0 | I40: 6 | J40: 3 | K40: =SUM(Table2[[#This Row],[ASSISTIVE PENCIL GRIP]:[UTENSIL HOLDER]]) -> 22 | L40: =Table2[[#This Row],[DEVICE COUNT]]-Table2[[#This Row],[LOW PROFILE SWITCH]] -> 22
A41: BUDS REHABILITATION CENTRE PUZHAKATRI | B41: MALAPPURAM | C41: 9 | D41: 0 | E41: 1 | G41: 18 | H41: 0 | I41: 6 | J41: 0 | K41: =SUM(Table2[[#This Row],[ASSISTIVE PENCIL GRIP]:[UTENSIL HOLDER]]) -> 25 | L41: =Table2[[#This Row],[DEVICE COUNT]]-Table2[[#This Row],[LOW PROFILE SWITCH]] -> 25
A42: BUDS REHABILITATION NAYATHODE | B42: ERNAKULAM | C42: 1 | D42: 0 | G42: 3 | H42: 0 | I42: 0 | J42: 0 | K42: =SUM(Table2[[#This Row],[ASSISTIVE PENCIL GRIP]:[UTENSIL HOLDER]]) -> 3 | L42: =Table2[[#This Row],[DEVICE COUNT]]-Table2[[#This Row],[LOW PROFILE SWITCH]] -> 3
A43: BUDS SCHOOL ALANGAD | B43: ERNAKULAM | C43: 2 | D43: 0 | G43: 3 | H43: 0 | I43: 0 | J43: 3 | K43: =SUM(Table2[[#This Row],[ASSISTIVE PENCIL GRIP]:[UTENSIL HOLDER]]) -> 6 | L43: =Table2[[#This Row],[DEVICE COUNT]]-Table2[[#This Row],[LOW PROFILE SWITCH]] -> 6
A44: BUDS SCHOOL CHEMMARUTHY | B44: TRIVANDRUM | C44: 5 | D44: 2 | G44: 0 | H44: 6 | I44: 3 | J44: 0 | K44: =SUM(Table2[[#This Row],[ASSISTIVE PENCIL GRIP]:[UTENSIL HOLDER]]) -> 11 | L44: =Table2[[#This Row],[DEVICE COUNT]]-Table2[[#This Row],[LOW PROFILE SWITCH]] -> 11
A45: BUDS SCHOOL EDAVANAKADU | B45: ERNAKULAM | C45: 2 | D45: 0 | G45: 3 | H45: 0 | I45: 0 | J45: 3 | K45: =SUM(Table2[[#This Row],[ASSISTIVE PENCIL GRIP]:[UTENSIL HOLDER]]) -> 6 | L45: =Table2[[#This Row],[DEVICE COUNT]]-Table2[[#This Row],[LOW PROFILE SWITCH]] -> 6
...

Sheet 376 CONSOLIDATED
A1: COUNT | B1: DISTRICT | C1: STUDENT_ID | D1: STUDENT NAME | E1: DISABILITY | F1: BUDS SCHOOL | G1: LENGTH | H1: WIDTH | I1: SIZE1 | J1: SIZE2 | K1: SIZE3 | L1: PREFERENCE
A2: 1 | B2: ERNAKULAM | C2: EKM-001-001 | D2: Adithyan Manoj | E2: CP | F2: ADARSH SCHOOL | L2: Assistive Pencil Grip
A3: 2 | B3: ERNAKULAM | C3: EKM-001-002 | D3: Athen | E3: autism | F3: ADARSH SCHOOL | G3: 5.26cm | H3: 2.37cm | I3: ND-08 | J3: ND-03 | K3: ND-07 | L3: Palm Pen Holder
A4: 3 | B4: ERNAKULAM | C4: EKM-001-003 | D4: Athmik S Krishna | E4: CP | F4: ADARSH SCHOOL | G4: 4.95 cm | H4: 1.97 cm | I4: ND-01 | J4: ND-03 | K4: ND-07 | L4: Utensil Holder
A5: 4 | B5: ERNAKULAM | C5: EKM-001-004 | D5: Ishan Krishna | E5: CP | F5: ADARSH SCHOOL | G5: 4.98 cm | H5: 2.17 cm | L5: Button Aid
A6: 5 | B6: ERNAKULAM | C6: EKM-001-005 | D6: Kevin Shaji | E6: CP/ID | F6: ADARSH SCHOOL | L6: Button Aid
A7: 6 | B7: ERNAKULAM | C7: EKM-001-006 | D7: Sidharth | E7: CP | F7: ADARSH SCHOOL | G7: 6.35 cm | H7: 2.34 cm | I7: ND-08 | J7: ND-05 | K7: ND-07 | L7: Utensil Holder
A8: 7 | B8: ERNAKULAM | C8: EKM-001-007 | D8: Sreeparvathy | E8: CP | F8: ADARSH SCHOOL | G8: 6.67cm | H8: 2.35cm | I8: ND-08 | J8: ND-10 | K8: ND-14 | L8: Palm Pen Holder
A9: 8 | B9: ERNAKULAM | C9: EKM-001-008 | D9: Vibin K Babu | E9: CP | F9: ADARSH SCHOOL | G9: 7.84 cm | H9: 2.92 cm | L9: Button Aid
A10: 9 | B10: PALAKKAD | C10: PAL-001-001 | D10: Anbu | E10: ID | F10: AGALI BUDS | G10: 4.25 cm | H10: 2.15cm | L10: Assistive Pencil Grip
A11: 10 | B11: PALAKKAD | C11: PAL-001-002 | D11: Mallieswaran | E11: ID | F11: AGALI BUDS | G11: 7.02cm | H11: 2.88cm | I11: ND-10 | J11: ND-14 | K11: ND-11 | L11: Palm Pen Holder
A12: 11 | B12: PALAKKAD | C12: PAL-001-003 | D12: Manikandan | E12: ID | F12: AGALI BUDS | L12: LOW PROFILE SWITCH
A13: 12 | B13: PALAKKAD | C13: PAL-001-005 | D13: Oviya | E13: autism | F13: AGALI BUDS | G13: 4.59cm | H13: 1.75cm | L13: Button Aid
A14: 13 | B14: THRISSUR | C14: TSR-001-001 | D14: Abhinandh | E14: MR | F14: ANTHIKKAD BLOCK PANCHAYATH BUDS | G14: 6.38 cm | H14: 2.36 cm | I14: ND-08 | J14: ND-10 | K14: ND-14 | L14: TOOTH BRUSH ADAPTER
A15: 14 | B15: THRISSUR | C15: TSR-001-002 | D15: Adithya K | E15: MR | F15: ANTHIKKAD BLOCK PANCHAYATH BUDS | L15: LOW PROFILE SWITCH
A16: 15 | B16: THRISSUR | C16: TSR-001-003 | D16: Asha Thomas | E16: MR | F16: ANTHIKKAD BLOCK PANCHAYATH BUDS | G16: 6.54 cm | H16: 1.93 cm | L16: Button Aid
A17: 16 | B17: THRISSUR | C17: TSR-001-004 | D17: Dilsha | E17: MR | F17: ANTHIKKAD BLOCK PANCHAYATH BUDS | G17: 6.31 cm | H17: 2.09 cm | L17: Button Aid
A18: 17 | B18: THRISSUR | C18: TSR-001-005 | D18: Hanan O A | E18: CP | F18: ANTHIKKAD BLOCK PANCHAYATH BUDS | L18: LOW PROFILE SWITCH
A19: 18 | B19: THRISSUR | C19: TSR-001-006 | D19: Neeranjana | E19: CP/MR | F19: ANTHIKKAD BLOCK PANCHAYATH BUDS | G19: 5.64 cm | H19: 2.04 cm | I19: ND-08 | J19: ND-03 | K19: ND-07 | L19: Palm Pen Holder
A20: 19 | B20: THRISSUR | C20: TSR-001-007 | D20: Pavithra A P | E20: MR | F20: ANTHIKKAD BLOCK PANCHAYATH BUDS | L20: LOW PROFILE SWITCH
A21: 20 | B21: THRISSUR | C21: TSR-001-008 | D21: Sheham | E21: MR | F21: ANTHIKKAD BLOCK PANCHAYATH BUDS | G21: 7.67 cm | H21: 2.35 cm | I21: RB-01 | J21: RB-02 | L21: Reading Bar - Curved
A22: 21 | B22: THRISSUR | C22: TSR-001-009 | D22: Shiva Krishna | E22: MR/Down syndrome | F22: ANTHIKKAD BLOCK PANCHAYATH BUDS | G22: 6.38 cm | H22: 2.09 cm | I22: ND-08 | J22: ND-05 | K22: ND-07 | L22: TOOTH BRUSH ADAPTER
A23: 22 | B23: ALAPPUZHA | C23: ALP-001-002 | D23: ANATHAKRISHNAN V M | E23: AUTISM SEVER | F23: ARDRA BUDS SCHOOL CHERTHALA | G23: 8 cm | H23: 2.59 cm | I23: ND-15 | J23: ND-19 | K23: ND-16 | L23: Utensil Holder
A24: 23 | B24: ALAPPUZHA | C24: ALP-001-004 | D24: DIYA C DELIP | E24: AUTISM | F24: ARDRA BUDS SCHOOL CHERTHALA | G24: 8 cm | H24: 2.6 cm | I24: ND-15 | J24: ND-19 | K24: ND-16 | L24: TOOTH BRUSH ADAPTER
A25: 24 | B25: ALAPPUZHA | C25: ALP-001-005 | D25: JOYAL PAULOSE | E25: MR | F25: ARDRA BUDS SCHOOL CHERTHALA | G25: 6.58 cm | H25: 2.24 cm | I25: RB-01 | J25: RB-02 | L25: Reading Bar - Curved
A26: 25 | B26: ALAPPUZHA | C26: ALP-001-006 | D26: MAHADEEV P V | E26: AUTISM SEVER | F26: ARDRA BUDS SCHOOL CHERTHALA | G26: 7.5 cm | H26: 2.8 cm | I26: ND-10 | J26: ND-14 | K26: ND-11 | L26: Utensil Holder
A27: 26 | B27: ALAPPUZHA | C27: ALP-001-007 | D27: NERANJANA LAL | E27: MR | F27: ARDRA BUDS SCHOOL CHERTHALA | G27: 4.83 cm | H27: 1.69 cm | I27: ND-01 | J27: ND-03 | K27: ND-07 | L27: TOOTH BRUSH ADAPTER
A28: 27 | B28: ALAPPUZHA | C28: ALP-001-009 | D28: SACHIN | E28: AUTISM | F28: ARDRA BUDS SCHOOL CHERTHALA | G28: 7 cm | H28: 2 cm | I28: ND-15 | J28: ND-10 | K28: ND-14 | L28: TOOTH BRUSH ADAPTER
A29: 28 | B29: KOLLAM | C29: KLM-001-001 | D29: Abhijith | E29: Intellectual Disability | F29: BODHINI BUDS SCHOOL | G29: 8.56cm | H29: 2.47cm | I29: RB-01 | J29: RB-02 | L29: Reading Bar - Curved
A30: 29 | B30: KOLLAM | C30: KLM-001-002 | D30: Ashwin Krishnan | E30: Autistic Spectrum Disorder | F30: BODHINI BUDS SCHOOL | G30: 6.16cm | H30: 2.54cm | I30: ND-08 | J30: ND-05 | K30: ND-07 | L30: TOOTH BRUSH ADAPTER
A31: 30 | B31: KOLLAM | C31: KLM-001-005 | D31: Hrishikesh Aravind | E31: Intellectual Disability | F31: BODHINI BUDS SCHOOL | G31: 6.94cm | H31: 2.73cm | I31: ND-08 | J31: ND-10 | K31: ND-14 | L31: TOOTH BRUSH ADAPTER
A32: 31 | B32: KOLLAM | C32: KLM-001-006 | D32: Janika M P | E32: Intellectual Disability | F32: BODHINI BUDS SCHOOL | G32: 7.08cm | H32: 2.98cm | I32: ND-10 | J32: ND-14 | K32: ND-11 | L32: TOOTH BRUSH ADAPTER
A33: 32 | B33: KOLLAM | C33: KLM-001-007 | D33: Muhamad Alfin | E33: Intellectual Disability | F33: BODHINI BUDS SCHOOL | G33: 7.48cm | H33: 2.37cm | I33: ND-15 | J33: ND-10 | K33: ND-14 | L33: TOOTH BRUSH ADAPTER
A34: 33 | B34: KOLLAM | C34: KLM-001-008 | D34: Muhammed Ihan | E34: Intellectual disability | F34: BODHINI BUDS SCHOOL | G34: 6.78 cm | H34: 2.83 cm | I34: ND-07 | J34: ND-09 | K34: ND-13 | L34: TOOTH BRUSH ADAPTER
A35: 34 | B35: KOLLAM | C35: KLM-001-009 | D35: Muhammed Thameem | E35: Intellectual Disability | F35: BODHINI BUDS SCHOOL | G35: 6.23cm | H35: 2.47cm | I35: ND-08 | J35: ND-05 | K35: ND-07 | L35: TOOTH BRUSH ADAPTER
A36: 35 | B36: KOLLAM | C36: KLM-001-010 | D36: Nithan | E36: Intellectual Disability | F36: BODHINI BUDS SCHOOL | G36: 6.32cm | H36: 2.65cm | I36: ND-08 | J36: ND-10 | K36: ND-14 | L36: TOOTH BRUSH ADAPTER
A37: 36 | B37: KOLLAM | C37: KLM-001-011 | D37: Prajapati R | E37: MR | F37: BODHINI BUDS SCHOOL | L37: Button Aid
A38: 37 | B38: KOLLAM | C38: KLM-001-012 | D38: Rubeena | E38: Intellectual Disability | F38: BODHINI BUDS SCHOOL | G38: 5.89cm | H38: 2.43cm | I38: ND-08 | J38: ND-03 | K38: ND-07 | L38: TOOTH BRUSH ADAPTER
A39: 38 | B39: KOLLAM | C39: KLM-001-013 | D39: Sanjay Rajesh | E39: Intellectual Disability | F39: BODHINI BUDS SCHOOL | G39: 7.52cm | H39: 3.08cm | I39: ND-10 | J39: ND-14 | K39: ND-11 | L39: TOOTH BRUSH ADAPTER
A40: 39 | B40: KOLLAM | C40: KLM-001-014 | D40: Suhail S Jaffir | E40: Autistic Spectrum Disorder,MR | F40: BODHINI BUDS SCHOOL | G40: 7.68cm | H40: 2.67cm | I40: ND-15 | J40: ND-10 | K40: ND-14 | L40: TOOTH BRUSH ADAPTER
...

Sheet all 50 LPS
A1: COUNT | B1: DISTRICT | C1: STUDENT_ID | D1: STUDENT NAME | E1: DISABILITY | F1: BUDS SCHOOL | G1: LENGTH | H1: WIDTH | I1: SIZE1 | J1: SIZE2 | K1: SIZE3 | L1: PREFERENCE
A2: 1 | B2: ALAPPUZHA | C2: ALP-004-001 | D2: Almeena Fathima | E2: CP | F2: SANJOE SADAN SPECIAL SCHOOL THURAVOOR | L2: LOW PROFILE SWITCH
A3: 2 | B3: ALAPPUZHA | C3: ALP-004-002 | D3: Alphia Fathima | E3: Down syndrome | F3: SANJOE SADAN SPECIAL SCHOOL THURAVOOR | L3: LOW PROFILE SWITCH
A4: 3 | B4: ALAPPUZHA | C4: ALP-004-004 | D4: Amay Prashanth | E4: CP/MR | F4: SANJOE SADAN SPECIAL SCHOOL THURAVOOR | L4: LOW PROFILE SWITCH | P4: Sl. No. | Q4: DISTRICTS | R4: STUDENTS | S4: DEVICES
A5: 4 | B5: ALAPPUZHA | C5: ALP-004-017 | D5: Phinehas Joseph | E5: Hyper active/Autism | F5: SANJOE SADAN SPECIAL SCHOOL THURAVOOR | L5: LOW PROFILE SWITCH | P5: 1 | Q5: TRIVANDRUM | R5: =COUNTIF($B$2:$B$503,Q5) -> 8 | S5: {=SUMPRODUCT(($B$2:$B$503=Q5)*($K$2:$M$503<>""))} -> 8
A6: 5 | B6: ALAPPUZHA | C6: ALP-004-019 | D6: Rudradev Lalush | E6: Hyper active | F6: SANJOE SADAN SPECIAL SCHOOL THURAVOOR | L6: LOW PROFILE SWITCH | P6: 2 | Q6: KOLLAM | R6: =COUNTIF($B$2:$B$503,Q6) -> 7 | S6: {=SUMPRODUCT(($B$2:$B$503=Q6)*($K$2:$M$503<>""))} -> 7
A7: 6 | B7: ERNAKULAM | C7: EKM-009-001 | D7: Abin Benny | E7: MR | F7: BUDS SCHOOL KOOVAPADY | L7: LOW PROFILE SWITCH | P7: 3 | Q7: Pathanamthitta | R7: =COUNTIF($B$2:$B$503,Q7) -> 7 | S7: {=SUMPRODUCT(($B$2:$B$503=Q7)*($K$2:$M$503<>""))} -> 7
A8: 7 | B8: ERNAKULAM | C8: EKM-009-002 | D8: Abith George | E8: MR | F8: BUDS SCHOOL KOOVAPADY | L8: LOW PROFILE SWITCH | P8: 4 | Q8: ALAPPUZHA | R8: =COUNTIF($B$2:$B$503,Q8) -> 5 | S8: {=SUMPRODUCT(($B$2:$B$503=Q8)*($K$2:$M$503<>""))} -> 5
A9: 8 | B9: ERNAKULAM | C9: EKM-003-002 | D9: Badusha T K | E9: MR | F9: BUD SCHOOL PAIPRA | L9: LOW PROFILE SWITCH | P9: 5 | Q9: Kottayam | R9: =COUNTIF($B$2:$B$503,Q9) -> 3 | S9: {=SUMPRODUCT(($B$2:$B$503=Q9)*($K$2:$M$503<>""))} -> 3
A10: 9 | B10: ERNAKULAM | C10: EKM-003-007 | D10: Teenu Thomas | E10: MR | F10: BUD SCHOOL PAIPRA | L10: LOW PROFILE SWITCH | P10: 6 | Q10: IDUKKI | R10: =COUNTIF($B$2:$B$503,Q10) -> 5 | S10: {=SUMPRODUCT(($B$2:$B$503=Q10)*($K$2:$M$503<>""))} -> 5
A11: 10 | B11: ERNAKULAM | C11: EKM-004-003 | D11: Asif haneefa | E11: MR | F11: BUD SCHOOL PALLARIMANGALAM | L11: LOW PROFILE SWITCH | P11: 7 | Q11: ERNAKULAM | R11: =COUNTIF($B$2:$B$503,Q11) -> 6 | S11: {=SUMPRODUCT(($B$2:$B$503=Q11)*($K$2:$M$503<>""))} -> 6
A12: 11 | B12: ERNAKULAM | C12: EKM-004-006 | D12: Fazila K A | E12: MR | F12: BUD SCHOOL PALLARIMANGALAM | L12: LOW PROFILE SWITCH | P12: 8 | Q12: Thrissur | R12: =COUNTIF($B$2:$B$503,Q12) -> 4 | S12: {=SUMPRODUCT(($B$2:$B$503=Q12)*($K$2:$M$503<>""))} -> 4
A13: 12 | B13: IDUKKI | C13: IDK-001-003 | D13: Gincy James | E13: ID | F13: KUMILY BUDS | L13: LOW PROFILE SWITCH | P13: 9 | Q13: PALAKKAD | R13: =COUNTIF($B$2:$B$503,Q13) -> 1 | S13: {=SUMPRODUCT(($B$2:$B$503=Q13)*($K$2:$M$503<>""))} -> 1
A14: 13 | B14: IDUKKI | C14: IDK-001-004 | D14: Rafia Rasheed | E14: ID | F14: KUMILY BUDS | L14: LOW PROFILE SWITCH | P14: 10 | Q14: malappuram | R14: =COUNTIF($B$2:$B$503,Q14) -> 4 | S14: {=SUMPRODUCT(($B$2:$B$503=Q14)*($K$2:$M$503<>""))} -> 4
A15: 14 | B15: IDUKKI | C15: IDK-001-005 | D15: Shiyas K S | E15: ID | F15: KUMILY BUDS | L15: LOW PROFILE SWITCH | P15: 11 | Q15: KOZHIKODE | R15: =COUNTIF($B$2:$B$503,Q15) -> 0 | S15: {=SUMPRODUCT(($B$2:$B$503=Q15)*($K$2:$M$503<>""))} -> 0
A16: 15 | B16: IDUKKI | C16: IDK-001-006 | D16: Soji K Soman | E16: ID | F16: KUMILY BUDS | L16: LOW PROFILE SWITCH | P16: 12 | Q16: Wayanad | R16: =COUNTIF($B$2:$B$503,Q16) -> 0 | S16: {=SUMPRODUCT(($B$2:$B$503=Q16)*($K$2:$M$503<>""))} -> 0
... A18: 17 | B18: KOLLAM | C18: KLM-004-002 | D18: Ameya J | E18: Intellectual Disability | F18: BUDS SPECIAL SCHOOL MAYYANAD | L18: LOW PROFILE SWITCH | P18: 14 | Q18: KAZARGOD | R18: =COUNTIF($B$2:$B$503,Q18) -> 0 | S18: {=SUMPRODUCT(($B$2:$B$503=Q18)*($K$2:$M$503<>""))} -> 0
A19: 18 | B19: KOLLAM | C19: KLM-004-006 | D19: Asiya N Sidhik | E19: Cerebral Palsy | F19: BUDS SPECIAL SCHOOL MAYYANAD | L19: LOW PROFILE SWITCH | R19: =SUBTOTAL(109,R5:R18) -> 50 | S19: =SUBTOTAL(109,S5:S18) -> 50
A20: 19 | B20: KOLLAM | C20: KLM-004-009 | D20: Ebin Robinson | E20: Autistic Spectrum Disorder | F20: BUDS SPECIAL SCHOOL MAYYANAD | L20: LOW PROFILE SWITCH
A21: 20 | B21: KOLLAM | C21: KLM-004-011 | D21: Fathima Shafeek | E21: Downsyndrome | F21: BUDS SPECIAL SCHOOL MAYYANAD | L21: LOW PROFILE SWITCH
A22: 21 | B22: KOLLAM | C22: KLM-004-019 | D22: Salman J | E22: Cerebral Palsy | F22: BUDS SPECIAL SCHOOL MAYYANAD | L22: LOW PROFILE SWITCH
A23: 22 | B23: KOLLAM | C23: KLM-006-004 | D23: Amal Krishna | E23: Down syndrome | F23: KADAKKAL GRAMAPANCHAYATH BUDS SCHOOL AND REHABILITATION CENTER | L23: LOW PROFILE SWITCH
A24: 23 | B24: KOLLAM | C24: KLM-008-002 | D24: Aditya Maheshwaran A | E24: Intellectual Disability | F24: PERINAD BUDS SCHOOL | L24: LOW PROFILE SWITCH
A25: 24 | B25: KOTTAYAM | C25: KTY-001-002 | D25: B Hariharanandanan | E25: Intellectual Disability | F25: THRIKKODITHANAM BUDS SPECIAL SCHOOL | L25: LOW PROFILE SWITCH
A26: 25 | B26: KOTTAYAM | C26: KTY-001-004 | D26: Dyan Kalesh | E26: Intellectual Disability | F26: THRIKKODITHANAM BUDS SPECIAL SCHOOL | L26: LOW PROFILE SWITCH
A27: 26 | B27: KOTTAYAM | C27: KTY-001-008 | D27: Shahid N | E27: Intellectual Disability | F27: THRIKKODITHANAM BUDS SPECIAL SCHOOL | L27: LOW PROFILE SWITCH
A28: 27 | B28: MALAPPURAM | C28: MLP-004-002 | D28: AJEEB k | E28: CP | F28: PURATHUR BUDS | L28: LOW PROFILE SWITCH
A29: 28 | B29: MALAPPURAM | C29: MLP-004-011 | D29: THEJAS KRISHNA | E29: ID | F29: PURATHUR BUDS | L29: LOW PROFILE SWITCH
A30: 29 | B30: MALAPPURAM | C30: MLP-005-003 | D30: ADITHYAN PR | E30: CP | F30: SPECTRUM BUDS SCHOOL | L30: LOW PROFILE SWITCH
A31: 30 | B31: MALAPPURAM | C31: MLP-005-018 | D31: SREEHARI | E31: ID | F31: SPECTRUM BUDS SCHOOL | L31: LOW PROFILE SWITCH
... A51: 50 | B51: TRIVANDRUM | C51: TVM-007-017 | D51: Shahid S | E51: Intellectual Disability | F51: STAR BUDS SCHOOL MARANALLOOR | L51: LOW PROFILE SWITCH

Sheet ALL 498 CONSOLIDATED NEW
A1: COUNT | B1: DISTRICT | C1: STUDENT_ID | D1: STUDENT NAME | E1: AGE | F1: DISABILITY | G1: BUDS SCHOOL | H1: TEACHER'S NAME | I1: LENGTH | J1: WIDTH | K1: SIZE1 | L1: SIZE2 | M1: SIZE3 | N1: PREFERENCE
A2: 1 | B2: TRIVANDRUM | C2: TVM-002-001 | D2: Abhijith B | E2: 22 | F2: MR | G2: BUDS SCHOOL POOVACHAL | H2: Ponnambili J | I2: 7.82cm | J2: 3.21cm | K2: ND-10 | L2: ND-14 | M2: ND-11 | N2: Utensil Holder | R2: Sl. No. | S2: ITEM | T2: STUDENTS | U2: DEVICES | V2: KDISC STOCK | W2: ADARSH STOCK | X2: VALAKKAYAM STOCK | Y2: ORDERED | Z2: Pending purchase | AA2: Column1
A3: 2 | B3: TRIVANDRUM | C3: TVM-002-002 | D3: Abin A V | E3: 17 | F3: Cerebral Palsy (70%) | G3: BUDS SCHOOL POOVACHAL | H3: Ponnambili J | K3: ND-999 | L3: ND-999 | N3: Assistive Pencil Grip | R3: 1 | S3: Assistive Pencil Grip | T3: =COUNTIF($N$2:$N$503,S3) -> 55 | U3: =COUNTIF($N$2:$N$503,S3)*2 -> 110 | V3: 82 | W3: 11 | X3: 0 | Y3: 100 | Z3: =U3-V3-W3 -> 17 | AA3: PENCIL
A4: 3 | B4: TRIVANDRUM | C4: TVM-002-003 | D4: Abina A S | E4: 17 | F4: Intellectual Disability (70%) | G4: BUDS SCHOOL POOVACHAL | H4: Ponnambili J | I4: 4.2cm | J4: 1.2cm | K4: ND-01 | L4: ND-03 | M4: ND-07 | N4: TOOTH BRUSH ADAPTER | R4: 2 | S4: Button Aid | T4: =COUNTIF($N$2:$N$503,S4) -> 35 | U4: =COUNTIF($N$2:$N$503,S4)*1 -> 35 | V4: NA | W4: NA | X4: NA | Y4: NA
A5: 4 | B5: TRIVANDRUM | C5: TVM-002-004 | D5: Adwaith A Ani | E5: 13 | F5: Cerebral Palsy (85%) | G5: BUDS SCHOOL POOVACHAL | H5: Ponnambili J | K5: ND-999 | L5: ND-999 | N5: Assistive Pencil Grip | R5: 3 | S5: LOW PROFILE SWITCH | T5: =COUNTIF($N$2:$N$503,S5) -> 25 | U5: =COUNTIF($N$2:$N$503,S5)*1 -> 25 | V5: NA | W5: NA | X5: NA | Y5: NA
A6: 5 | B6: TRIVANDRUM | C6: TVM-002-005 | D6: Alan R | E6: 12 | F6: Autistic Spectrum Disorder(70%) | G6: BUDS SCHOOL POOVACHAL | H6: Ponnambili J | I6: 6 cm | J6: 1.5 cm | K6: ND-15 | L6: ND-08 | M6: ND-10 | N6: TOOTH BRUSH ADAPTER | R6: 4 | S6: Palm Pen Holder | T6: =COUNTIF($N$2:$N$503,S6) -> 126 | U6: =COUNTIF($N$2:$N$503,S6)*3 -> 378 | V6: 87 | W6: 7 | X6: 0 | Y6: 100 | Z6: =U6-V6-W6 -> 284 | AA6: PEN
A7: 6 | B7: TRIVANDRUM | C7: TVM-002-006 | D7: Alan V | E7: 12 | F7: Intellectual Disability (75%) | G7: BUDS SCHOOL POOVACHAL | H7: Ponnambili J | K7: NDL-09 | N7: Button Aid | R7: 5 | S7: Reading Bar - Curved | T7: =COUNTIF($N$2:$N$503,S7) -> 39 | U7: =COUNTIF($N$2:$N$503,S7)*2 -> 78 | V7: NA | W7: NA | X7: NA | Y7: NA
A8: 7 | B8: TRIVANDRUM | C8: TVM-002-007 | D8: Aleena R S | E8: 13 | F8: Intellectual Disability (60%) | G8: BUDS SCHOOL POOVACHAL | H8: Ponnambili J | K8: RB-01 | L8: RB-02 | N8: Reading Bar - Curved | R8: 6 | S8: TOOTH BRUSH ADAPTER | T8: =COUNTIF($N$2:$N$503,S8) -> 98 | U8: =COUNTIF($N$2:$N$503,S8)*3 -> 294 | V8: 51 | W8: 9 | X8: 0 | Y8: 60 | Z8: =U8-V8-W8 -> 234 | AA8: TOOTHBRUSH
A9: 8 | B9: TRIVANDRUM | C9: TVM-002-008 | D9: Alona S Ajith | E9: 6 | F9: Autistic Spectrum Disorder(90%) | G9: BUDS SCHOOL POOVACHAL | H9: Ponnambili J | I9: 4.2cm | J9: 1.5cm | K9: ND-01 | L9: ND-03 | M9: ND-07 | N9: Palm Pen Holder | R9: 7 | S9: Utensil Holder | T9: =COUNTIF($N$2:$N$503,S9) -> 124 | U9: =COUNTIF($N$2:$N$503,S9)*3 -> 372 | V9: 108 | W9: 13 | X9: 0 | Y9: 120 | Z9: =U9-V9-W9 -> 251 | AA9: SPOON/FORK
A10: 9 | B10: TRIVANDRUM | C10: TVM-002-009 | D10: Amal Krishna | E10: 17 | F10: Intellectual Disability (60%) | G10: BUDS SCHOOL POOVACHAL | H10: Ponnambili J | K10: RB-01 | L10: RB-02 | N10: Reading Bar - Curved | S10: TOTAL | T10: =SUM(T3:T9) -> 502 | U10: =SUM(U3:U9) -> 1292 | V10: 127 | W10: 24 | X10: 100 | Y10: 958 | Z10: =T10-V10-W10 -> 351 | AA10: BOXES
A11: 10 | B11: TRIVANDRUM | C11: TVM-002-010 | D11: Anagha Ajayan | E11: 18 | F11: Cerebral Palsy (80%) | G11: BUDS SCHOOL POOVACHAL | H11: Ponnambili J | K11: ND-999 | L11: ND-999 | N11: Assistive Pencil Grip | V11: 32 | W11: 100 | X11: 100 | Z11: =T10-V11-W11 -> 370 | AA11: GREETINGS
A12: 11 | B12: TRIVANDRUM | C12: TVM-002-011 | D12: Anagha Anilkumar | E12: 16 | F12: CP-70% | G12: BUDS SCHOOL POOVACHAL | H12: Ponnambili J | K12: ND-999 | L12: ND-999 | N12: Assistive Pencil Grip | S12: NUMBER OF SCHOOLS | T12: =COUNTA(_xlfn.UNIQUE(G2:G503)) -> 51
A13: 12 | B13: TRIVANDRUM | C13: TVM-002-012 | D13: Ananya D S | E13: 14 | F13: ID-75% | G13: BUDS SCHOOL POOVACHAL | H13: Ponnambili J | K13: RB-01 | L13: RB-02 | N13: Reading Bar - Curved | X13: w/0 LPS
A14: 13 | B14: TRIVANDRUM | C14: TVM-002-013 | D14: Anees B S | E14: 22 | F14: MR, Downsyndrome | G14: BUDS SCHOOL POOVACHAL | H14: Ponnambili J | I14: 7.81cm | J14: 2.77cm | K14: ND-10 | L14: ND-14 | M14: ND-11 | N14: TOOTH BRUSH ADAPTER | R14: Sl. No. | S14: DISTRICTS | T14: STUDENTS | U14: DEVICES | W14: Sl. No. | X14: DISTRICTS | Y14: STUDENTS | Z14: DEVICES
A15: 14 | B15: TRIVANDRUM | C15: TVM-002-014 | D15: Aromal T | E15: 20 | F15: Intellectual Disability | G15: BUDS SCHOOL POOVACHAL | H15: Ponnambili J | I15: 7.65cm | J15: 3.23cm | K15: ND-10 | L15: ND-14 | M15: ND-11 | N15: Palm Pen Holder | R15: 1 | S15: TRIVANDRUM | T15: =COUNTIF($B$2:$B$503,S15) -> 96 | U15: {=SUMPRODUCT(($B$2:$B$503=S15)*($K$2:$M$503<>""))} -> 215 | W15: 1 | X15: TRIVANDRUM | Y15: {=SUMPRODUCT(($B$2:$B$503=X15)*($N$2:$N$503<>"LOW PROFILE SWITCH"))} -> 88 | Z15: {=SUMPRODUCT(($B$2:$B$503=X15)*($K$2:$M$503<>"")*($K$2:$M$503<>"LP-999"))} -> 207
A16: 15 | B16: TRIVANDRUM | C16: TVM-002-015 | D16: Hina Fathima | E16: 12 | F16: Intellectual disability, Multiple disability-85% | G16: BUDS SCHOOL POOVACHAL | H16: Ponnambili J | I16: 6.7cm | J16: 2cm | K16: ND-08 | L16: ND-05 | M16: ND-07 | N16: Utensil Holder | R16: 2 | S16: KOLLAM | T16: =COUNTIF($B$2:$B$503,S16) -> 122 | U16: {=SUMPRODUCT(($B$2:$B$503=S16)*($K$2:$M$503<>""))} -> 308 | W16: 2 | X16: KOLLAM | Y16: {=SUMPRODUCT(($B$2:$B$503=X16)*($N$2:$N$503<>"LOW PROFILE SWITCH"))} -> 117 | Z16: {=SUMPRODUCT(($B$2:$B$503=X16)*($K$2:$M$503<>"")*($K$2:$M$503<>"LP-999"))} -> 303
A17: 16 | B17: TRIVANDRUM | C17: TVM-002-016 | D17: Kasinadh V M | E17: 15 | F17: Intellectual Disability (50%) | G17: BUDS SCHOOL POOVACHAL | H17: Ponnambili J | K17: ND-999 | L17: ND-999 | N17: Assistive Pencil Grip | R17: 3 | S17: Pathanamthitta | T17: =COUNTIF($B$2:$B$503,S17) -> 27 | U17: {=SUMPRODUCT(($B$2:$B$503=S17)*($K$2:$M$503<>""))} -> 60 | W17: 3 | X17: Pathanamthitta | Y17: {=SUMPRODUCT(($B$2:$B$503=X17)*($N$2:$N$503<>"LOW PROFILE SWITCH"))} -> 27 | Z17: {=SUMPRODUCT(($B$2:$B$503=X17)*($K$2:$M$503<>"")*($K$2:$M$503<>"LP-999"))} -> 60
A18: 17 | B18: TRIVANDRUM | C18: TVM-002-017 | D18: Navaneeth R S | E18: 12 | F18: Intellectual Disability 45% | G18: BUDS SCHOOL POOVACHAL | H18: Ponnambili J | K18: RB-01 | L18: RB-02 | N18: Reading Bar - Curved | R18: 4 | S18: ALAPPUZHA | T18: =COUNTIF($B$2:$B$503,S18) -> 54 | U18: {=SUMPRODUCT(($B$2:$B$503=S18)*($K$2:$M$503<>""))} -> 156 | W18: 4 | X18: ALAPPUZHA | Y18: {=SUMPRODUCT(($B$2:$B$503=X18)*($N$2:$N$503<>"LOW PROFILE SWITCH"))} -> 54 | Z18: {=SUMPRODUCT(($B$2:$B$503=X18)*($K$2:$M$503<>"")*($K$2:$M$503<>"LP-999"))} -> 156
A19: 18 | B19: TRIVANDRUM | C19: TVM-002-018 | D19: Nayana R S | E19: 14 | F19: Intellectual Disability-60% | G19: BUDS SCHOOL POOVACHAL | H19: Ponnambili J | K19: RB-01 | L19: RB-02 | N19: Reading Bar - Curved | R19: 5 | S19: Kottayam | T19: =COUNTIF($B$2:$B$503,S19) -> 9 | U19: {=SUMPRODUCT(($B$2:$B$503=S19)*($K$2:$M$503<>""))} -> 20 | W19: 5 | X19: Kottayam | Y19: {=SUMPRODUCT(($B$2:$B$503=X19)*($N$2:$N$503<>"LOW PROFILE SWITCH"))} -> 6 | Z19: {=SUMPRODUCT(($B$2:$B$503=X19)*($K$2:$M$503<>"")*($K$2:$M$503<>"LP-999"))} -> 17
A20: 19 | B20: TRIVANDRUM | C20: TVM-002-019 | D20: Nidina M | E20: 17 | F20: Cerebral Palsy -90% | G20: BUDS SCHOOL POOVACHAL | H20: Ponnambili J | K20: ND-999 | L20: ND-999 | N20: Assistive Pencil Grip | R20: 6 | S20: IDUKKI | T20: =COUNTIF($B$2:$B$503,S20) -> 16 | U20: {=SUMPRODUCT(($B$2:$B$503=S20)*($K$2:$M$503<>""))} -> 46 | W20: 6 | X20: IDUKKI | Y20: {=SUMPRODUCT(($B$2:$B$503=X20)*($N$2:$N$503<>"LOW PROFILE SWITCH"))} -> 15 | Z20: {=SUMPRODUCT(($B$2:$B$503=X20)*($K$2:$M$503<>"")*($K$2:$M$503<>"LP-999"))} -> 45
A21: 20 | B21: TRIVANDRUM | C21: TVM-002-020 | D21: Nikhil S S | E21: 10 | F21: Hearing Impaired-71% | G21: BUDS SCHOOL POOVACHAL | H21: Ponnambili J | I21: 4.2cm | J21: 1.5cm | K21: ND-01 | L21: ND-03 | M21: ND-07 | N21: Palm Pen Holder | R21: 7 | S21: ERNAKULAM | T21: =COUNTIF($B$2:$B$503,S21) -> 40 | U21: {=SUMPRODUCT(($B$2:$B$503=S21)*($K$2:$M$503<>""))} -> 97 | W21: 7 | X21: ERNAKULAM | Y21: {=SUMPRODUCT(($B$2:$B$503=X21)*($N$2:$N$503<>"LOW PROFILE SWITCH"))} -> 32 | Z21: {=SUMPRODUCT(($B$2:$B$503=X21)*($K$2:$M$503<>"")*($K$2:$M$503<>"LP-999"))} -> 89
A22: 21 | B22: TRIVANDRUM | C22: TVM-002-021 | D22: Parvathy S H | E22: 15 | F22: Intellectual Disability (90%) | G22: BUDS SCHOOL POOVACHAL | H22: Ponnambili J | I22: 2 cm | J22: 4.5cm | K22: ND-07 | L22: ND-09 | M22: ND-06 | N22: TOOTH BRUSH ADAPTER | R22: 8 | S22: Thrissur | T22: =COUNTIF($B$2:$B$503,S22) -> 21 | U22: {=SUMPRODUCT(($B$2:$B$503=S22)*($K$2:$M$503<>""))} -> 55 | W22: 8 | X22: Thrissur | Y22: {=SUMPRODUCT(($B$2:$B$503=X22)*($N$2:$N$503<>"LOW PROFILE SWITCH"))} -> 21 | Z22: {=SUMPRODUCT(($B$2:$B$503=X22)*($K$2:$M$503<>"")*($K$2:$M$503<>"LP-999"))} -> 55
A23: 22 | B23: TRIVANDRUM | C23: TVM-002-022 | D23: Sreyas B N | E23: 13 | F23: Cerebral Palsy (70%) | G23: BUDS SCHOOL POOVACHAL | H23: Ponnambili J | K23: NDL-09 | N23: Button Aid | R23: 9 | S23: PALAKKAD | T23: =COUNTIF($B$2:$B$503,S23) -> 24 | U23: {=SUMPRODUCT(($B$2:$B$503=S23)*($K$2:$M$503<>""))} -> 65 | W23: 9 | X23: PALAKKAD | Y23: {=SUMPRODUCT(($B$2:$B$503=X23)*($N$2:$N$503<>"LOW PROFILE SWITCH"))} -> 24 | Z23: {=SUMPRODUCT(($B$2:$B$503=X23)*($K$2:$M$503<>"")*($K$2:$M$503<>"LP-999"))} -> 65
A24: 23 | B24: TRIVANDRUM | C24: TVM-002-023 | D24: Sudha | E24: 32 | F24: Intellectual Disability | G24: BUDS SCHOOL POOVACHAL | H24: Ponnambili J | I24: 7.22cm | J24: 3.12cm | K24: ND-10 | L24: ND-14 | M24: ND-11 | N24: Palm Pen Holder | R24: 10 | S24: malappuram | T24: =COUNTIF($B$2:$B$503,S24) -> 52 | U24: {=SUMPRODUCT(($B$2:$B$503=S24)*($K$2:$M$503<>""))} -> 147 | W24: 10 | X24: malappuram | Y24: {=SUMPRODUCT(($B$2:$B$503=X24)*($N$2:$N$503<>"LOW PROFILE SWITCH"))} -> 52 | Z24: {=SUMPRODUCT(($B$2:$B$503=X24)*($K$2:$M$503<>"")*($K$2:$M$503<>"LP-999"))} -> 147
A25: 24 | B25: TRIVANDRUM | C25: TVM-002-024 | D25: Surya Narayanan S | E25: 12 | F25: Autism -45% | G25: BUDS SCHOOL POOVACHAL | H25: Ponnambili J | K25: NDL-09 | N25: Button Aid | R25: 11 | S25: KOZHIKODE | T25: =COUNTIF($B$2:$B$503,S25) -> 8 | U25: {=SUMPRODUCT(($B$2:$B$503=S25)*($K$2:$M$503<>""))} -> 24 | W25: 11 | X25: KOZHIKODE | Y25: {=SUMPRODUCT(($B$2:$B$503=X25)*($N$2:$N$503<>"LOW PROFILE SWITCH"))} -> 8 | Z25: {=SUMPRODUCT(($B$2:$B$503=X25)*($K$2:$M$503<>"")*($K$2:$M$503<>"LP-999"))} -> 24
A26: 25 | B26: TRIVANDRUM | C26: TVM-002-025 | D26: Vyshnavi S | E26: 14 | F26: Intellectual Disability-60% | G26: BUDS SCHOOL POOVACHAL | H26: Ponnambili J | K26: NDL-09 | N26: Button Aid | R26: 12 | S26: Wayanad | T26: =COUNTIF($B$2:$B$503,S26) -> 10 | U26: {=SUMPRODUCT(($B$2:$B$503=S26)*($K$2:$M$503<>""))} -> 30 | W26: 12 | X26: Wayanad | Y26: {=SUMPRODUCT(($B$2:$B$503=X26)*($N$2:$N$503<>"LOW PROFILE SWITCH"))} -> 10 | Z26: {=SUMPRODUCT(($B$2:$B$503=X26)*($K$2:$M$503<>"")*($K$2:$M$503<>"LP-999"))} -> 30
A27: 26 | B27: TRIVANDRUM | C27: TVM-003-001 | D27: Abhinaya | E27: 20 | F27: Intellectual Disability (mild) | G27: MAHATHMAJI BUDS SCHOOL VILAPPILSALA | H27: Suji K A | I27: 6.75 cm | J27: 3 cm | K27: ND-999 | L27: ND-999 | N27: Assistive Pencil Grip | R27: 13 | S27: Kannur | T27: =COUNTIF($B$2:$B$503,S27) -> 11 | U27: {=SUMPRODUCT(($B$2:$B$503=S27)*($K$2:$M$503<>""))} -> 33 | W27: 13 | X27: Kannur | Y27: {=SUMPRODUCT(($B$2:$B$503=X27)*($N$2:$N$503<>"LOW PROFILE SWITCH"))} -> 11 | Z27: {=SUMPRODUCT(($B$2:$B$503=X27)*($K$2:$M$503<>"")*($K$2:$M$503<>"LP-999"))} -> 33
A28: 27 | B28: TRIVANDRUM | C28: TVM-003-002 | D28: Anand | E28: 25 | F28: Intellectual disability( Severe) | G28: MAHATHMAJI BUDS SCHOOL VILAPPILSALA | H28: Suji K A | I28: 7.3 cm | J28: 3.1 cm | K28: ND-10 | L28: ND-14 | M28: ND-11 | N28: TOOTH BRUSH ADAPTER | R28: 14 | S28: KAZARGOD | T28: =COUNTIF($B$2:$B$503,S28) -> 12 | U28: {=SUMPRODUCT(($B$2:$B$503=S28)*($K$2:$M$503<>""))} -> 36 | W28: 14 | X28: KAZARGOD | Y28: {=SUMPRODUCT(($B$2:$B$503=X28)*($N$2:$N$503<>"LOW PROFILE SWITCH"))} -> 12 | Z28: {=SUMPRODUCT(($B$2:$B$503=X28)*($K$2:$M$503<>"")*($K$2:$M$503<>"LP-999"))} -> 36
A29: 28 | B29: TRIVANDRUM | C29: TVM-003-005 | D29: Kalyani | E29: 16 | F29: Cerebral Palsy | G29: MAHATHMAJI BUDS SCHOOL VILAPPILSALA | H29: Suji K A | I29: 5cm | J29: 2.1 cm | K29: ND-08 | L29: ND-03 | M29: ND-07 | N29: Utensil Holder | T29: =SUBTOTAL(109,T15:T28) -> 502 | U29: =SUBTOTAL(109,U15:U28) -> 1292 | Y29: =SUBTOTAL(109,Y15:Y28) -> 477 | Z29: =SUBTOTAL(109,Z15:Z28) -> 1267
A30: 29 | B30: TRIVANDRUM | C30: TVM-003-006 | D30: Karthika | E30: 18 | F30: Intellectual Disability | G30: MAHATHMAJI BUDS SCHOOL VILAPPILSALA | H30: Suji K A | I30: 7.90 cm | J30: 3cm | K30: RB-01 | L30: RB-02 | N30: Reading Bar - Curved
A31: 30 | B31: TRIVANDRUM | C31: TVM-003-007 | D31: Priyesh Chandran | E31: 25 | F31: Intellectual Disability (severe) | G31: MAHATHMAJI BUDS SCHOOL VILAPPILSALA | H31: Suji K A | I31: 7.97cm | J31: 3.34cm | K31: ND-14 | L31: ND-16 | M31: ND-20 | N31: Utensil Holder | R31: Sl. No. | S31: DISTRICTS | T31: LPS
A32: 31 | B32: TRIVANDRUM | C32: TVM-003-008 | D32: Sandeep S R | E32: 15 | F32: Intellectual Disability(moderate) | G32: MAHATHMAJI BUDS SCHOOL VILAPPILSALA | H32: Suji K A | I32: 7.5cm | J32: 3cm | K32: ND-10 | L32: ND-14 | M32: ND-11 | N32: Utensil Holder | R32: 1 | S32: TRIVANDRUM | T32: {=SUMPRODUCT(($B$2:$B$503=S32)*($N$2:$N$503="LOW PROFILE SWITCH"))} -> 8
A33: 32 | B33: TRIVANDRUM | C33: TVM-003-009 | D33: Arun | E33: 25 | F33: Cerebral Palsy | G33: MAHATHMAJI BUDS SCHOOL VILAPPILSALA | H33: Suji K A | I33: 7.95 cm | J33: 2 cm | K33: ND-08 | L33: ND-05 | M33: ND-07 | N33: Utensil Holder | R33: 2 | S33: KOLLAM | T33: {=SUMPRODUCT(($B$2:$B$503=S33)*($N$2:$N$503="LOW PROFILE SWITCH"))} -> 5
A34: 33 | B34: TRIVANDRUM | C34: TVM-003-010 | D34: Bhagyanath | E34: 11 | F34: Cerebral Palsy | G34: MAHATHMAJI BUDS SCHOOL VILAPPILSALA | H34: Suji K A | I34: 4.5 cm | J34: 1.7 cm | K34: ND-01 | L34: ND-03 | M34: ND-07 | N34: Utensil Holder | R34: 3 | S34: Pathanamthitta | T34: {=SUMPRODUCT(($B$2:$B$503=S34)*($N$2:$N$503="LOW PROFILE SWITCH"))} -> 0
A35: 34 | B35: TRIVANDRUM | C35: TVM-001-001 | D35: Abhiram M | E35: 8 | F35: Intellectual Disability | G35: BUDS SCHOOL CHEMMARUTHY | H35: Shani S | I35: 6.42cm | J35: 2.87cm | K35: ND-10 | L35: ND-14 | M35: ND-11 | N35: Utensil Holder | R35: 4 | S35: ALAPPUZHA | T35: {=SUMPRODUCT(($B$2:$B$503=S35)*($N$2:$N$503="LOW PROFILE SWITCH"))} -> 0
A36: 35 | B36: TRIVANDRUM | C36: TVM-001-002 | D36: Adarsh MS | E36: 23 | F36: Cerebral Palsy | G36: BUDS SCHOOL CHEMMARUTHY | H36: Shani S | K36: LP-999 | N36: LOW PROFILE SWITCH | R36: 5 | S36: Kottayam | T36: {=SUMPRODUCT(($B$2:$B$503=S36)*($N$2:$N$503="LOW PROFILE SWITCH"))} -> 3
A37: 36 | B37: TRIVANDRUM | C37: TVM-001-003 | D37: Aliya Laji | E37: 22 | F37: Intellectual disability | G37: BUDS SCHOOL CHEMMARUTHY | H37: Shani S | K37: RB-01 | L37: RB-02 | N37: Reading Bar - Curved | R37: 6 | S37: IDUKKI | T37: {=SUMPRODUCT(($B$2:$B$503=S37)*($N$2:$N$503="LOW PROFILE SWITCH"))} -> 1
A38: 37 | B38: TRIVANDRUM | C38: TVM-001-004 | D38: Chithu J | E38: 28 | F38: Cerebral Palsy | G38: BUDS SCHOOL CHEMMARUTHY | H38: Shani S | K38: RB-01 | L38: RB-02 | N38: Reading Bar - Curved | R38: 7 | S38: ERNAKULAM | T38: {=SUMPRODUCT(($B$2:$B$503=S38)*($N$2:$N$503="LOW PROFILE SWITCH"))} -> 8
A39: 38 | B39: TRIVANDRUM | C39: TVM-001-005 | D39: Devika Ashok | E39: 26 | F39: DownSyndrome | G39: BUDS SCHOOL CHEMMARUTHY | H39: Shani S | I39: 7.17cm | J39: 2.81cm | K39: ND-10 | L39: ND-14 | M39: ND-11 | N39: Palm Pen Holder | R39: 8 | S39: Thrissur | T39: {=SUMPRODUCT(($B$2:$B$503=S39)*($N$2:$N$503="LOW PROFILE SWITCH"))} -> 0
A40: 39 | B40: TRIVANDRUM | C40: TVM-001-006 | D40: Gayathri L P | E40: 21 | F40: Intellectual Disability | G40: BUDS SCHOOL CHEMMARUTHY | H40: Shani S | I40: 6.91cm | J40: 2.85cm | K40: ND-10 | L40: ND-14 | M40: ND-11 | N40: TOOTH BRUSH ADAPTER | R40: 9 | S40: PALAKKAD | T40: {=SUMPRODUCT(($B$2:$B$503=S40)*($N$2:$N$503="LOW PROFILE SWITCH"))} -> 0
...

Sheet device distribution TVM 
A1: Palm Pen Holder | C1: Total | D1: Printed | E1: Pending | F1: TOOTH BRUSH ADAPTER | H1: Total | I1: Printed | J1: Pending | K1: Utensil Holder | M1: Total | N1: Printed | O1: Pending | P1: Reading Bar - Curved | R1: Total | S1: Printed | T1: Pending | U1: Assistive Pencil Grip | W1: Total | X1: Printed | Y1: Pending | Z1: Button Aid | AB1: Total | AC1: Printed | AD1: Pending | AE1: LOW PROFILE SWITCH | AG1: Total | AH1: Printed | AI1: Pending | AL1: SCHOOL LIST
A2: ND-01 | B2: 302102001 | C2: {=SUMPRODUCT(('ALL 498 CONSOLIDATED NEW'!$N$2:$N$503=A$1)*(A2='ALL 498 CONSOLIDATED NEW'!$K$2:$M$503)*(ISNUMBER(MATCH('ALL 498 CONSOLIDATED NEW'!$G$2:$G$503,Table171314[SCHOOL LIST],0))))} -> 2 | D2: 2 | E2: =C2-D2 -> 0 | F2: ND-01 | G2: 101103001 | H2: {=SUMPRODUCT(('ALL 498 CONSOLIDATED NEW'!$N$2:$N$503=F$1)*(F2='ALL 498 CONSOLIDATED NEW'!$K$2:$M$503)*(ISNUMBER(MATCH('ALL 498 CONSOLIDATED NEW'!$G$2:$G$503,Table171314[SCHOOL LIST],0))))} -> 1 | I2: 1 | J2: =H2-I2 -> 0 | K2: ND-01 | L2: 105101001 | M2: {=SUMPRODUCT(('ALL 498 CONSOLIDATED NEW'!$N$2:$N$503=K$1)*(K2='ALL 498 CONSOLIDATED NEW'!$K$2:$M$503)*(ISNUMBER(MATCH('ALL 498 CONSOLIDATED NEW'!$G$2:$G$503,Table171314[SCHOOL LIST],0))))} -> 2 | N2: 2 | O2: =M2-N2 -> 0 | P2: RB-01 | Q2: 302202001 | R2: {=SUMPRODUCT(('ALL 498 CONSOLIDATED NEW'!$N$2:$N$503=P$1)*(P2='ALL 498 CONSOLIDATED NEW'!$K$2:$M$503)*(ISNUMBER(MATCH('ALL 498 CONSOLIDATED NEW'!$G$2:$G$503,Table171314[SCHOOL LIST],0))))} -> 15 | S2: 15 | T2: =R2-S2 -> 0 | U2: ND-999 | V2: 301201999 | W2: {=SUMPRODUCT(('ALL 498 CONSOLIDATED NEW'!$N$2:$N$503=U$1)*(U2='ALL 498 CONSOLIDATED NEW'!$K$2:$M$503)*(ISNUMBER(MATCH('ALL 498 CONSOLIDATED NEW'!$G$2:$G$503,Table171314[SCHOOL LIST],0))))} -> 36 | X2: 36 | Y2: =W2-X2 -> 0 | Z2: NDL-09 | AA2: 104104009 | AB2: {=SUMPRODUCT(('ALL 498 CONSOLIDATED NEW'!$N$2:$N$503=Z$1)*(Z2='ALL 498 CONSOLIDATED NEW'!$K$2:$M$503)*(ISNUMBER(MATCH('ALL 498 CONSOLIDATED NEW'!$G$2:$G$503,Table171314[SCHOOL LIST],0))))} -> 12 | AC2: 3 | AD2: =AB2-AC2 -> 9 | AE2: LP-999 | AF2: 204301999 | AG2: {=SUMPRODUCT(('ALL 498 CONSOLIDATED NEW'!$N$2:$N$503=AE$1)*(AE2='ALL 498 CONSOLIDATED NEW'!$K$2:$M$503)*(ISNUMBER(MATCH('ALL 498 CONSOLIDATED NEW'!$G$2:$G$503,Table171314[SCHOOL LIST],0))))} -> 8 | AH2: 0 | AI2: =AG2-AH2 -> 8 | AL2: MAHATHMAJI BUDS SCHOOL VILAPPILSALA
A3: ND-02 | B3: 302102002 | C3: {=SUMPRODUCT(('ALL 498 CONSOLIDATED NEW'!$N$2:$N$503=A$1)*(A3='ALL 498 CONSOLIDATED NEW'!$K$2:$M$503)*(ISNUMBER(MATCH('ALL 498 CONSOLIDATED NEW'!$G$2:$G$503,Table171314[SCHOOL LIST],0))))} -> 0 | D3: 0 | E3: =C3-D3 -> 0 | F3: ND-02 | G3: 101103002 | H3: {=SUMPRODUCT(('ALL 498 CONSOLIDATED NEW'!$N$2:$N$503=F$1)*(F3='ALL 498 CONSOLIDATED NEW'!$K$2:$M$503)*(ISNUMBER(MATCH('ALL 498 CONSOLIDATED NEW'!$G$2:$G$503,Table171314[SCHOOL LIST],0))))} -> 0 | I3: 0 | J3: =H3-I3 -> 0 | K3: ND-02 | L3: 105101002 | M3: {=SUMPRODUCT(('ALL 498 CONSOLIDATED NEW'!$N$2:$N$503=K$1)*(K3='ALL 498 CONSOLIDATED NEW'!$K$2:$M$503)*(ISNUMBER(MATCH('ALL 498 CONSOLIDATED NEW'!$G$2:$G$503,Table171314[SCHOOL LIST],0))))} -> 0 | N3: 0 | O3: =M3-N3 -> 0 | P3: RB-02 | Q3: 302202002 | R3: {=SUMPRODUCT(('ALL 498 CONSOLIDATED NEW'!$N$2:$N$503=P$1)*(P3='ALL 498 CONSOLIDATED NEW'!$K$2:$M$503)*(ISNUMBER(MATCH('ALL 498 CONSOLIDATED NEW'!$G$2:$G$503,Table171314[SCHOOL LIST],0))))} -> 15 | S3: 15 | T3: =R3-S3 -> 0 | AL3: BUDS SCHOOL POOVACHAL | AM3: Sl. No. | AN3: ITEM | AO3: STUDENTS
A4: ND-03 | B4: 302102003 | C4: {=SUMPRODUCT(('ALL 498 CONSOLIDATED NEW'!$N$2:$N$503=A$1)*(A4='ALL 498 CONSOLIDATED NEW'!$K$2:$M$503)*(ISNUMBER(MATCH('ALL 498 CONSOLIDATED NEW'!$G$2:$G$503,Table171314[SCHOOL LIST],0))))} -> 2 | D4: 2 | E4: =C4-D4 -> 0 | F4: ND-03 | G4: 101103003 | H4: {=SUMPRODUCT(('ALL 498 CONSOLIDATED NEW'!$N$2:$N$503=F$1)*(F4='ALL 498 CONSOLIDATED NEW'!$K$2:$M$503)*(ISNUMBER(MATCH('ALL 498 CONSOLIDATED NEW'!$G$2:$G$503,Table171314[SCHOOL LIST],0))))} -> 2 | I4: 2 | J4: =H4-I4 -> 0 | K4: ND-03 | L4: 105101003 | M4: {=SUMPRODUCT(('ALL 498 CONSOLIDATED NEW'!$N$2:$N$503=K$1)*(K4='ALL 498 CONSOLIDATED NEW'!$K$2:$M$503)*(ISNUMBER(MATCH('ALL 498 CONSOLIDATED NEW'!$G$2:$G$503,Table171314[SCHOOL LIST],0))))} -> 3 | N4: 3 | O4: =M4-N4 -> 0 | AL4: NAVJYOTHI BUDS SCHOOL PALLICHAL | AM4: 1 | AN4: Palm Pen Holder | AO4: =C22/3 -> 14
A5: ND-04 | B5: 302102004 | C5: {=SUMPRODUCT(('ALL 498 CONSOLIDATED NEW'!$N$2:$N$503=A$1)*(A5='ALL 498 CONSOLIDATED NEW'!$K$2:$M$503)*(ISNUMBER(MATCH('ALL 498 CONSOLIDATED NEW'!$G$2:$G$503,Table171314[SCHOOL LIST],0))))} -> 0 | D5: 0 | E5: =C5-D5 -> 0 | F5: ND-04 | G5: 101103004 | H5: {=SUMPRODUCT(('ALL 498 CONSOLIDATED NEW'!$N$2:$N$503=F$1)*(F5='ALL 498 CONSOLIDATED NEW'!$K$2:$M$503)*(ISNUMBER(MATCH('ALL 498 CONSOLIDATED NEW'!$G$2:$G$503,Table171314[SCHOOL LIST],0))))} -> 0 | I5: 0 | J5: =H5-I5 -> 0 | K5: ND-04 | L5: 105101004 | M5: {=SUMPRODUCT(('ALL 498 CONSOLIDATED NEW'!$N$2:$N$503=K$1)*(K5='ALL 498 CONSOLIDATED NEW'!$K$2:$M$503)*(ISNUMBER(MATCH('ALL 498 CONSOLIDATED NEW'!$G$2:$G$503,Table171314[SCHOOL LIST],0))))} -> 0 | N5: 0 | O5: =M5-N5 -> 0 | AL5: STAR BUDS SCHOOL MARANALLOOR | AM5: 2 | AN5: TOOTH BRUSH ADAPTER | AO5: =H22/3 -> 11
A6: ND-05 | B6: 302102005 | C6: {=SUMPRODUCT(('ALL 498 CONSOLIDATED NEW'!$N$2:$N$503=A$1)*(A6='ALL 498 CONSOLIDATED NEW'!$K$2:$M$503)*(ISNUMBER(MATCH('ALL 498 CONSOLIDATED NEW'!$G$2:$G$503,Table171314[SCHOOL LIST],0))))} -> 0 | D6: 0 | E6: =C6-D6 -> 0 | F6: ND-05 | G6: 101103005 | H6: {=SUMPRODUCT(('ALL 498 CONSOLIDATED NEW'!$N$2:$N$503=F$1)*(F6='ALL 498 CONSOLIDATED NEW'!$K$2:$M$503)*(ISNUMBER(MATCH('ALL 498 CONSOLIDATED NEW'!$G$2:$G$503,Table171314[SCHOOL LIST],0))))} -> 1 | I6: 1 | J6: =H6-I6 -> 0 | K6: ND-05 | L6: 105101005 | M6: {=SUMPRODUCT(('ALL 498 CONSOLIDATED NEW'!$N$2:$N$503=K$1)*(K6='ALL 498 CONSOLIDATED NEW'!$K$2:$M$503)*(ISNUMBER(MATCH('ALL 498 CONSOLIDATED NEW'!$G$2:$G$503,Table171314[SCHOOL LIST],0))))} -> 3 | N6: 3 | O6: =M6-N6 -> 0 | AL6: NEDUMANGAD MUNCIPALITY BUDS SCHOOL | AM6: 3 | AN6: Utensil Holder | AO6: =M22/3 -> 18
A7: ND-06 | B7: 302102006 | C7: {=SUMPRODUCT(('ALL 498 CONSOLIDATED NEW'!$N$2:$N$503=A$1)*(A7='ALL 498 CONSOLIDATED NEW'!$K$2:$M$503)*(ISNUMBER(MATCH('ALL 498 CONSOLIDATED NEW'!$G$2:$G$503,Table171314[SCHOOL LIST],0))))} -> 0 | D7: 0 | E7: =C7-D7 -> 0 | F7: ND-06 | G7: 101103006 | H7: {=SUMPRODUCT(('ALL 498 CONSOLIDATED NEW'!$N$2:$N$503=F$1)*(F7='ALL 498 CONSOLIDATED NEW'!$K$2:$M$503)*(ISNUMBER(MATCH('ALL 498 CONSOLIDATED NEW'!$G$2:$G$503,Table171314[SCHOOL LIST],0))))} -> 1 | I7: 1 | J7: =H7-I7 -> 0 | K7: ND-06 | L7: 105101006 | M7: {=SUMPRODUCT(('ALL 498 CONSOLIDATED NEW'!$N$2:$N$503=K$1)*(K7='ALL 498 CONSOLIDATED NEW'!$K$2:$M$503)*(ISNUMBER(MATCH('ALL 498 CONSOLIDATED NEW'!$G$2:$G$503,Table171314[SCHOOL LIST],0))))} -> 0 | N7: 0 | O7: =M7-N7 -> 0 | AL7: BUDS SCHOOL CHEMMARUTHY | AM7: 4 | AN7: Reading Bar - Curved | AO7: =R22/2 -> 15
A8: ND-07 | B8: 302102007 | C8: {=SUMPRODUCT(('ALL 498 CONSOLIDATED NEW'!$N$2:$N$503=A$1)*(A8='ALL 498 CONSOLIDATED NEW'!$K$2:$M$503)*(ISNUMBER(MATCH('ALL 498 CONSOLIDATED NEW'!$G$2:$G$503,Table171314[SCHOOL LIST],0))))} -> 2 | D8: 2 | E8: =C8-D8 -> 0 | F8: ND-07 | G8: 101103007 | H8: {=SUMPRODUCT(('ALL 498 CONSOLIDATED NEW'!$N$2:$N$503=F$1)*(F8='ALL 498 CONSOLIDATED NEW'!$K$2:$M$503)*(ISNUMBER(MATCH('ALL 498 CONSOLIDATED NEW'!$G$2:$G$503,Table171314[SCHOOL LIST],0))))} -> 4 | I8: 4 | J8: =H8-I8 -> 0 | K8: ND-07 | L8: 105101007 | M8: {=SUMPRODUCT(('ALL 498 CONSOLIDATED NEW'!$N$2:$N$503=K$1)*(K8='ALL 498 CONSOLIDATED NEW'!$K$2:$M$503)*(ISNUMBER(MATCH('ALL 498 CONSOLIDATED NEW'!$G$2:$G$503,Table171314[SCHOOL LIST],0))))} -> 6 | N8: 6 | O8: =M8-N8 -> 0 | AL8: SANTHWANAM BUDS SCHOOL CHIRAYINKEEZHU | AM8: 5 | AN8: Assistive Pencil Grip | AO8: =W22/2 -> 18
A9: ND-08 | B9: 302102008 | C9: {=SUMPRODUCT(('ALL 498 CONSOLIDATED NEW'!$N$2:$N$503=A$1)*(A9='ALL 498 CONSOLIDATED NEW'!$K$2:$M$503)*(ISNUMBER(MATCH('ALL 498 CONSOLIDATED NEW'!$G$2:$G$503,Table171314[SCHOOL LIST],0))))} -> 4 | D9: 4 | E9: =C9-D9 -> 0 | F9: ND-08 | G9: 101103008 | H9: {=SUMPRODUCT(('ALL 498 CONSOLIDATED NEW'!$N$2:$N$503=F$1)*(F9='ALL 498 CONSOLIDATED NEW'!$K$2:$M$503)*(ISNUMBER(MATCH('ALL 498 CONSOLIDATED NEW'!$G$2:$G$503,Table171314[SCHOOL LIST],0))))} -> 5 | I9: 5 | J9: =H9-I9 -> 0 | K9: ND-08 | L9: 105101008 | M9: {=SUMPRODUCT(('ALL 498 CONSOLIDATED NEW'!$N$2:$N$503=K$1)*(K9='ALL 498 CONSOLIDATED NEW'!$K$2:$M$503)*(ISNUMBER(MATCH('ALL 498 CONSOLIDATED NEW'!$G$2:$G$503,Table171314[SCHOOL LIST],0))))} -> 4 | N9: 4 | O9: =M9-N9 -> 0 | AL9: ELAKAMON GRAMAPANCHAYATH BUDS SCHOOL | AM9: 6 | AN9: Button Aid | AO9: =AB22 -> 12
A10: ND-09 | B10: 302102009 | C10: {=SUMPRODUCT(('ALL 498 CONSOLIDATED NEW'!$N$2:$N$503=A$1)*(A10='ALL 498 CONSOLIDATED NEW'!$K$2:$M$503)*(ISNUMBER(MATCH('ALL 498 CONSOLIDATED NEW'!$G$2:$G$503,Table171314[SCHOOL LIST],0))))} -> 0 | D10: 0 | E10: =C10-D10 -> 0 | F10: ND-09 | G10: 101103009 | H10: {=SUMPRODUCT(('ALL 498 CONSOLIDATED NEW'!$N$2:$N$503=F$1)*(F10='ALL 498 CONSOLIDATED NEW'!$K$2:$M$503)*(ISNUMBER(MATCH('ALL 498 CONSOLIDATED NEW'!$G$2:$G$503,Table171314[SCHOOL LIST],0))))} -> 1 | I10: 1 | J10: =H10-I10 -> 0 | K10: ND-09 | L10: 105101009 | M10: {=SUMPRODUCT(('ALL 498 CONSOLIDATED NEW'!$N$2:$N$503=K$1)*(K10='ALL 498 CONSOLIDATED NEW'!$K$2:$M$503)*(ISNUMBER(MATCH('ALL 498 CONSOLIDATED NEW'!$G$2:$G$503,Table171314[SCHOOL LIST],0))))} -> 0 | N10: 0 | O10: =M10-N10 -> 0 | AM10: 7 | AN10: LOW PROFILE SWITCH | AO10: =AG22 -> 8
A11: ND-10 | B11: 302102010 | C11: {=SUMPRODUCT(('ALL 498 CONSOLIDATED NEW'!$N$2:$N$503=A$1)*(A11='ALL 498 CONSOLIDATED NEW'!$K$2:$M$503)*(ISNUMBER(MATCH('ALL 498 CONSOLIDATED NEW'!$G$2:$G$503,Table171314[SCHOOL LIST],0))))} -> 12 | D11: 12 | E11: =C11-D11 -> 0 | F11: ND-10 | G11: 101103010 | H11: {=SUMPRODUCT(('ALL 498 CONSOLIDATED NEW'!$N$2:$N$503=F$1)*(F11='ALL 498 CONSOLIDATED NEW'!$K$2:$M$503)*(ISNUMBER(MATCH('ALL 498 CONSOLIDATED NEW'!$G$2:$G$503,Table171314[SCHOOL LIST],0))))} -> 6 | I11: 6 | J11: =H11-I11 -> 0 | K11: ND-10 | L11: 105101010 | M11: {=SUMPRODUCT(('ALL 498 CONSOLIDATED NEW'!$N$2:$N$503=K$1)*(K11='ALL 498 CONSOLIDATED NEW'!$K$2:$M$503)*(ISNUMBER(MATCH('ALL 498 CONSOLIDATED NEW'!$G$2:$G$503,Table171314[SCHOOL LIST],0))))} -> 8 | N11: 8 | O11: =M11-N11 -> 0 | AN11: Total | AO11: =SUM(AO4:AO10) -> 96
A12: ND-11 | B12: 302102011 | C12: {=SUMPRODUCT(('ALL 498 CONSOLIDATED NEW'!$N$2:$N$503=A$1)*(A12='ALL 498 CONSOLIDATED NEW'!$K$2:$M$503)*(ISNUMBER(MATCH('ALL 498 CONSOLIDATED NEW'!$G$2:$G$503,Table171314[SCHOOL LIST],0))))} -> 6 | D12: 6 | E12: =C12-D12 -> 0 | F12: ND-11 | G12: 101103011 | H12: {=SUMPRODUCT(('ALL 498 CONSOLIDATED NEW'!$N$2:$N$503=F$1)*(F12='ALL 498 CONSOLIDATED NEW'!$K$2:$M$503)*(ISNUMBER(MATCH('ALL 498 CONSOLIDATED NEW'!$G$2:$G$503,Table171314[SCHOOL LIST],0))))} -> 3 | I12: 3 | J12: =H12-I12 -> 0 | K12: ND-11 | L12: 105101011 | M12: {=SUMPRODUCT(('ALL 498 CONSOLIDATED NEW'!$N$2:$N$503=K$1)*(K12='ALL 498 CONSOLIDATED NEW'!$K$2:$M$503)*(ISNUMBER(MATCH('ALL 498 CONSOLIDATED NEW'!$G$2:$G$503,Table171314[SCHOOL LIST],0))))} -> 8 | N12: 8 | O12: =M12-N12 -> 0 | AN12: w/o LPS | AO12: =SUM(AO4:AO9) -> 88
A13: ND-12 | B13: 302102012 | C13: {=SUMPRODUCT(('ALL 498 CONSOLIDATED NEW'!$N$2:$N$503=A$1)*(A13='ALL 498 CONSOLIDATED NEW'!$K$2:$M$503)*(ISNUMBER(MATCH('ALL 498 CONSOLIDATED NEW'!$G$2:$G$503,Table171314[SCHOOL LIST],0))))} -> 0 | D13: 0 | E13: =C13-D13 -> 0 | F13: ND-12 | G13: 101103012 | H13: {=SUMPRODUCT(('ALL 498 CONSOLIDATED NEW'!$N$2:$N$503=F$1)*(F13='ALL 498 CONSOLIDATED NEW'!$K$2:$M$503)*(ISNUMBER(MATCH('ALL 498 CONSOLIDATED NEW'!$G$2:$G$503,Table171314[SCHOOL LIST],0))))} -> 0 | I13: 0 | J13: =H13-I13 -> 0 | K13: ND-12 | L13: 105101012 | M13: {=SUMPRODUCT(('ALL 498 CONSOLIDATED NEW'!$N$2:$N$503=K$1)*(K13='ALL 498 CONSOLIDATED NEW'!$K$2:$M$503)*(ISNUMBER(MATCH('ALL 498 CONSOLIDATED NEW'!$G$2:$G$503,Table171314[SCHOOL LIST],0))))} -> 1 | N13: 1 | O13: =M13-N13 -> 0
A14: ND-13 | B14: 302102013 | C14: {=SUMPRODUCT(('ALL 498 CONSOLIDATED NEW'!$N$2:$N$503=A$1)*(A14='ALL 498 CONSOLIDATED NEW'!$K$2:$M$503)*(ISNUMBER(MATCH('ALL 498 CONSOLIDATED NEW'!$G$2:$G$503,Table171314[SCHOOL LIST],0))))} -> 0 | D14: 0 | E14: =C14-D14 -> 0 | F14: ND-13 | G14: 101103013 | H14: {=SUMPRODUCT(('ALL 498 CONSOLIDATED NEW'!$N$2:$N$503=F$1)*(F14='ALL 498 CONSOLIDATED NEW'!$K$2:$M$503)*(ISNUMBER(MATCH('ALL 498 CONSOLIDATED NEW'!$G$2:$G$503,Table171314[SCHOOL LIST],0))))} -> 0 | I14: 0 | J14: =H14-I14 -> 0 | K14: ND-13 | L14: 105101013 | M14: {=SUMPRODUCT(('ALL 498 CONSOLIDATED NEW'!$N$2:$N$503=K$1)*(K14='ALL 498 CONSOLIDATED NEW'!$K$2:$M$503)*(ISNUMBER(MATCH('ALL 498 CONSOLIDATED NEW'!$G$2:$G$503,Table171314[SCHOOL LIST],0))))} -> 0 | N14: 0 | O14: =M14-N14 -> 0
A15: ND-14 | B15: 302102014 | C15: {=SUMPRODUCT(('ALL 498 CONSOLIDATED NEW'!$N$2:$N$503=A$1)*(A15='ALL 498 CONSOLIDATED NEW'!$K$2:$M$503)*(ISNUMBER(MATCH('ALL 498 CONSOLIDATED NEW'!$G$2:$G$503,Table171314[SCHOOL LIST],0))))} -> 12 | D15: 12 | E15: =C15-D15 -> 0 | F15: ND-14 | G15: 101103014 | H15: {=SUMPRODUCT(('ALL 498 CONSOLIDATED NEW'!$N$2:$N$503=F$1)*(F15='ALL 498 CONSOLIDATED NEW'!$K$2:$M$503)*(ISNUMBER(MATCH('ALL 498 CONSOLIDATED NEW'!$G$2:$G$503,Table171314[SCHOOL LIST],0))))} -> 6 | I15: 6 | J15: =H15-I15 -> 0 | K15: ND-14 | L15: 105101014 | M15: {=SUMPRODUCT(('ALL 498 CONSOLIDATED NEW'!$N$2:$N$503=K$1)*(K15='ALL 498 CONSOLIDATED NEW'!$K$2:$M$503)*(ISNUMBER(MATCH('ALL 498 CONSOLIDATED NEW'!$G$2:$G$503,Table171314[SCHOOL LIST],0))))} -> 12 | N15: 12 | O15: =M15-N15 -> 0
A16: ND-15 | B16: 302102015 | C16: {=SUMPRODUCT(('ALL 498 CONSOLIDATED NEW'!$N$2:$N$503=A$1)*(A16='ALL 498 CONSOLIDATED NEW'!$K$2:$M$503)*(ISNUMBER(MATCH('ALL 498 CONSOLIDATED NEW'!$G$2:$G$503,Table171314[SCHOOL LIST],0))))} -> 2 | D16: 2 | E16: =C16-D16 -> 0 | F16: ND-15 | G16: 101103015 | H16: {=SUMPRODUCT(('ALL 498 CONSOLIDATED NEW'!$N$2:$N$503=F$1)*(F16='ALL 498 CONSOLIDATED NEW'!$K$2:$M$503)*(ISNUMBER(MATCH('ALL 498 CONSOLIDATED NEW'!$G$2:$G$503,Table171314[SCHOOL LIST],0))))} -> 1 | I16: 1 | J16: =H16-I16 -> 0 | K16: ND-15 | L16: 105101015 | M16: {=SUMPRODUCT(('ALL 498 CONSOLIDATED NEW'!$N$2:$N$503=K$1)*(K16='ALL 498 CONSOLIDATED NEW'!$K$2:$M$503)*(ISNUMBER(MATCH('ALL 498 CONSOLIDATED NEW'!$G$2:$G$503,Table171314[SCHOOL LIST],0))))} -> 0 | N16: 0 | O16: =M16-N16 -> 0
A17: ND-16 | B17: 302102016 | C17: {=SUMPRODUCT(('ALL 498 CONSOLIDATED NEW'!$N$2:$N$503=A$1)*(A17='ALL 498 CONSOLIDATED NEW'!$K$2:$M$503)*(ISNUMBER(MATCH('ALL 498 CONSOLIDATED NEW'!$G$2:$G$503,Table171314[SCHOOL LIST],0))))} -> 0 | D17: 0 | E17: =C17-D17 -> 0 | F17: ND-16 | G17: 101103016 | H17: {=SUMPRODUCT(('ALL 498 CONSOLIDATED NEW'!$N$2:$N$503=F$1)*(F17='ALL 498 CONSOLIDATED NEW'!$K$2:$M$503)*(ISNUMBER(MATCH('ALL 498 CONSOLIDATED NEW'!$G$2:$G$503,Table171314[SCHOOL LIST],0))))} -> 0 | I17: 0 | J17: =H17-I17 -> 0 | K17: ND-16 | L17: 105101016 | M17: {=SUMPRODUCT(('ALL 498 CONSOLIDATED NEW'!$N$2:$N$503=K$1)*(K17='ALL 498 CONSOLIDATED NEW'!$K$2:$M$503)*(ISNUMBER(MATCH('ALL 498 CONSOLIDATED NEW'!$G$2:$G$503,Table171314[SCHOOL LIST],0))))} -> 2 | N17: 2 | O17: =M17-N17 -> 0
A18: ND-17 | B18: 302102017 | C18: {=SUMPRODUCT(('ALL 498 CONSOLIDATED NEW'!$N$2:$N$503=A$1)*(A18='ALL 498 CONSOLIDATED NEW'!$K$2:$M$503)*(ISNUMBER(MATCH('ALL 498 CONSOLIDATED NEW'!$G$2:$G$503,Table171314[SCHOOL LIST],0))))} -> 0 | D18: 0 | E18: =C18-D18 -> 0 | F18: ND-17 | G18: 101103017 | H18: {=SUMPRODUCT(('ALL 498 CONSOLIDATED NEW'!$N$2:$N$503=F$1)*(F18='ALL 498 CONSOLIDATED NEW'!$K$2:$M$503)*(ISNUMBER(MATCH('ALL 498 CONSOLIDATED NEW'!$G$2:$G$503,Table171314[SCHOOL LIST],0))))} -> 0 | I18: 0 | J18: =H18-I18 -> 0 | K18: ND-17 | L18: 105101017 | M18: {=SUMPRODUCT(('ALL 498 CONSOLIDATED NEW'!$N$2:$N$503=K$1)*(K18='ALL 498 CONSOLIDATED NEW'!$K$2:$M$503)*(ISNUMBER(MATCH('ALL 498 CONSOLIDATED NEW'!$G$2:$G$503,Table171314[SCHOOL LIST],0))))} -> 0 | N18: 0 | O18: =M18-N18 -> 0
A19: ND-18 | B19: 302102018 | C19: {=SUMPRODUCT(('ALL 498 CONSOLIDATED NEW'!$N$2:$N$503=A$1)*(A19='ALL 498 CONSOLIDATED NEW'!$K$2:$M$503)*(ISNUMBER(MATCH('ALL 498 CONSOLIDATED NEW'!$G$2:$G$503,Table171314[SCHOOL LIST],0))))} -> 0 | D19: 0 | E19: =C19-D19 -> 0 | F19: ND-18 | G19: 101103018 | H19: {=SUMPRODUCT(('ALL 498 CONSOLIDATED NEW'!$N$2:$N$503=F$1)*(F19='ALL 498 CONSOLIDATED NEW'!$K$2:$M$503)*(ISNUMBER(MATCH('ALL 498 CONSOLIDATED NEW'!$G$2:$G$503,Table171314[SCHOOL LIST],0))))} -> 1 | I19: 1 | J19: =H19-I19 -> 0 | K19: ND-18 | L19: 105101018 | M19: {=SUMPRODUCT(('ALL 498 CONSOLIDATED NEW'!$N$2:$N$503=K$1)*(K19='ALL 498 CONSOLIDATED NEW'!$K$2:$M$503)*(ISNUMBER(MATCH('ALL 498 CONSOLIDATED NEW'!$G$2:$G$503,Table171314[SCHOOL LIST],0))))} -> 2 | N19: 2 | O19: =M19-N19 -> 0
A20: ND-19 | B20: 302102019 | C20: {=SUMPRODUCT(('ALL 498 CONSOLIDATED NEW'!$N$2:$N$503=A$1)*(A20='ALL 498 CONSOLIDATED NEW'!$K$2:$M$503)*(ISNUMBER(MATCH('ALL 498 CONSOLIDATED NEW'!$G$2:$G$503,Table171314[SCHOOL LIST],0))))} -> 0 | D20: 0 | E20: =C20-D20 -> 0 | F20: ND-19 | G20: 101103019 | H20: {=SUMPRODUCT(('ALL 498 CONSOLIDATED NEW'!$N$2:$N$503=F$1)*(F20='ALL 498 CONSOLIDATED NEW'!$K$2:$M$503)*(ISNUMBER(MATCH('ALL 498 CONSOLIDATED NEW'!$G$2:$G$503,Table171314[SCHOOL LIST],0))))} -> 0 | I20: 0 | J20: =H20-I20 -> 0 | K20: ND-19 | L20: 105101019 | M20: {=SUMPRODUCT(('ALL 498 CONSOLIDATED NEW'!$N$2:$N$503=K$1)*(K20='ALL 498 CONSOLIDATED NEW'!$K$2:$M$503)*(ISNUMBER(MATCH('ALL 498 CONSOLIDATED NEW'!$G$2:$G$503,Table171314[SCHOOL LIST],0))))} -> 0 | N20: 0 | O20: =M20-N20 -> 0
A21: ND-20 | B21: 302102020 | C21: {=SUMPRODUCT(('ALL 498 CONSOLIDATED NEW'!$N$2:$N$503=A$1)*(A21='ALL 498 CONSOLIDATED NEW'!$K$2:$M$503)*(ISNUMBER(MATCH('ALL 498 CONSOLIDATED NEW'!$G$2:$G$503,Table171314[SCHOOL LIST],0))))} -> 0 | D21: 0 | E21: =C21-D21 -> 0 | F21: ND-20 | G21: 101103020 | H21: {=SUMPRODUCT(('ALL 498 CONSOLIDATED NEW'!$N$2:$N$503=F$1)*(F21='ALL 498 CONSOLIDATED NEW'!$K$2:$M$503)*(ISNUMBER(MATCH('ALL 498 CONSOLIDATED NEW'!$G$2:$G$503,Table171314[SCHOOL LIST],0))))} -> 1 | I21: 1 | J21: =H21-I21 -> 0 | K21: ND-20 | L21: 105101020 | M21: {=SUMPRODUCT(('ALL 498 CONSOLIDATED NEW'!$N$2:$N$503=K$1)*(K21='ALL 498 CONSOLIDATED NEW'!$K$2:$M$503)*(ISNUMBER(MATCH('ALL 498 CONSOLIDATED NEW'!$G$2:$G$503,Table171314[SCHOOL LIST],0))))} -> 3 | N21: 3 | O21: =M21-N21 -> 0
B22: =A1 -> Palm Pen Holder | C22: =SUM(C2:C21) -> 42 | D22: =SUM(D2:D21) -> 42 | E22: =C22-D22 -> 0 | G22: =F1 -> TOOTH BRUSH ADAPTER | H22: =SUM(H2:H21) -> 33 | I22: =SUM(I2:I21) -> 33 | J22: =H22-I22 -> 0 | L22: =K1 -> Utensil Holder | M22: =SUM(M2:M21) -> 54 | N22: =SUM(N2:N21) -> 54 | O22: =M22-N22 -> 0 | Q22: =P1 -> Reading Bar - Curved | R22: =SUM(R2:R21) -> 30 | S22: =SUM(S2:S3) -> 30 | T22: =R22-S22 -> 0 | V22: =U1 -> Assistive Pencil Grip | W22: =SUM(W2:W21) -> 36 | X22: =SUM(X2:X3) -> 36 | Y22: =W22-X22 -> 0 | AA22: =Z1 -> Button Aid | AB22: =SUM(AB2:AB21) -> 12 | AC22: 12 | AD22: =AB22-AC22 -> 0 | AF22: =AE1 -> LOW PROFILE SWITCH | AG22: =SUM(AG2:AG21) -> 8 | AH22: =SUM(AH2:AH3) -> 0 | AI22: =AG22-AH22 -> 8 | AJ22: =SUM(AG22,C22,H22,M22,R22,W22,AB22) -> 215 | AK22: Total
AJ23: =SUM(C22,H22,M22,R22,W22,AB22) -> 207 | AK23: wihtout lps
AJ24: =SUM(E22,J22,O22,T22,Y22,AD22) -> 0 | AK24: pending w/o LPS

Sheet device distribution KLM 
A1: Palm Pen Holder | C1: Total | D1: Printed | E1: Pending | F1: TOOTH BRUSH ADAPTER | H1: Total | I1: Printed | J1: Pending | K1: Utensil Holder | M1: Total | N1: Printed | O1: Pending | P1: Reading Bar - Curved | R1: Total | S1: Printed | T1: Pending | U1: Assistive Pencil Grip | W1: Total | X1: Printed | Y1: Pending | Z1: Button Aid | AB1: Total | AC1: Printed | AD1: Pending | AE1: LOW PROFILE SWITCH | AG1: Total | AH1: Printed | AI1: Pending | AL1: SCHOOL LIST
A2: ND-01 | B2: 302102001 | C2: {=SUMPRODUCT(('ALL 498 CONSOLIDATED NEW'!$N$2:$N$503=A$1)*(A2='ALL 498 CONSOLIDATED NEW'!$K$2:$M$503)*(ISNUMBER(MATCH('ALL 498 CONSOLIDATED NEW'!$G$2:$G$503,Table1713141118[SCHOOL LIST],0))))} -> 0 | D2: 0 | E2: =C2-D2 -> 0 | F2: ND-01 | G2: 101103001 | H2: {=SUMPRODUCT(('ALL 498 CONSOLIDATED NEW'!$N$2:$N$503=F$1)*(F2='ALL 498 CONSOLIDATED NEW'!$K$2:$M$503)*(ISNUMBER(MATCH('ALL 498 CONSOLIDATED NEW'!$G$2:$G$503,Table1713141118[SCHOOL LIST],0))))} -> 0 | I2: 0 | J2: =H2-I2 -> 0 | K2: ND-01 | L2: 105101001 | M2: {=SUMPRODUCT(('ALL 498 CONSOLIDATED NEW'!$N$2:$N$503=K$1)*(K2='ALL 498 CONSOLIDATED NEW'!$K$2:$M$503)*(ISNUMBER(MATCH('ALL 498 CONSOLIDATED NEW'!$G$2:$G$503,Table1713141118[SCHOOL LIST],0))))} -> 3 | N2: 3 | O2: =M2-N2 -> 0 | P2: RB-01 | Q2: 302202001 | R2: {=SUMPRODUCT(('ALL 498 CONSOLIDATED NEW'!$N$2:$N$503=P$1)*(P2='ALL 498 CONSOLIDATED NEW'!$K$2:$M$503)*(ISNUMBER(MATCH('ALL 498 CONSOLIDATED NEW'!$G$2:$G$503,Table1713141118[SCHOOL LIST],0))))} -> 10 | S2: 10 | T2: =R2-S2 -> 0 | U2: ND-999 | V2: 301201999 | W2: {=SUMPRODUCT(('ALL 498 CONSOLIDATED NEW'!$N$2:$N$503=U$1)*(U2='ALL 498 CONSOLIDATED NEW'!$K$2:$M$503)*(ISNUMBER(MATCH('ALL 498 CONSOLIDATED NEW'!$G$2:$G$503,Table1713141118[SCHOOL LIST],0))))} -> 36 | X2: 36 | Y2: =W2-X2 -> 0 | Z2: NDL-09 | AA2: 104104009 | AB2: {=SUMPRODUCT(('ALL 498 CONSOLIDATED NEW'!$N$2:$N$503=Z$1)*(Z2='ALL 498 CONSOLIDATED NEW'!$K$2:$M$503)*(ISNUMBER(MATCH('ALL 498 CONSOLIDATED NEW'!$G$2:$G$503,Table1713141118[SCHOOL LIST],0))))} -> 10 | AC2: 0 | AD2: =AB2-AC2 -> 10 | AE2: LP-999 | AF2: 204301999 | AG2: {=SUMPRODUCT(('ALL 498 CONSOLIDATED NEW'!$N$2:$N$503=AE$1)*(AE2='ALL 498 CONSOLIDATED NEW'!$K$2:$M$503)*(ISNUMBER(MATCH('ALL 498 CONSOLIDATED NEW'!$G$2:$G$503,Table1713141118[SCHOOL LIST],0))))} -> 5 | AH2: 0 | AI2: =AG2-AH2 -> 5 | AL2: BUDS SPECIAL SCHOOL MAYYANAD
A3: ND-02 | B3: 302102002 | C3: {=SUMPRODUCT(('ALL 498 CONSOLIDATED NEW'!$N$2:$N$503=A$1)*(A3='ALL 498 CONSOLIDATED NEW'!$K$2:$M$503)*(ISNUMBER(MATCH('ALL 498 CONSOLIDATED NEW'!$G$2:$G$503,Table1713141118[SCHOOL LIST],0))))} -> 0 | D3: 0 | E3: =C3-D3 -> 0 | F3: ND-02 | G3: 101103002 | H3: {=SUMPRODUCT(('ALL 498 CONSOLIDATED NEW'!$N$2:$N$503=F$1)*(F3='ALL 498 CONSOLIDATED NEW'!$K$2:$M$503)*(ISNUMBER(MATCH('ALL 498 CONSOLIDATED NEW'!$G$2:$G$503,Table1713141118[SCHOOL LIST],0))))} -> 0 | I3: 0 | J3: =H3-I3 -> 0 | K3: ND-02 | L3: 105101002 | M3: {=SUMPRODUCT(('ALL 498 CONSOLIDATED NEW'!$N$2:$N$503=K$1)*(K3='ALL 498 CONSOLIDATED NEW'!$K$2:$M$503)*(ISNUMBER(MATCH('ALL 498 CONSOLIDATED NEW'!$G$2:$G$503,Table1713141118[SCHOOL LIST],0))))} -> 0 | N3: 0 | O3: =M3-N3 -> 0 | P3: RB-02 | Q3: 302202002 | R3: {=SUMPRODUCT(('ALL 498 CONSOLIDATED NEW'!$N$2:$N$503=P$1)*(P3='ALL 498 CONSOLIDATED NEW'!$K$2:$M$503)*(ISNUMBER(MATCH('ALL 498 CONSOLIDATED NEW'!$G$2:$G$503,Table1713141118[SCHOOL LIST],0))))} -> 10 | S3: 10 | T3: =R3-S3 -> 0 | AL3: BUDS SPECIAL SCHOOL ELAMPALLOOR | AM3: Sl. No. | AN3: ITEM | AO3: STUDENTS
A4: ND-03 | B4: 302102003 | C4: {=SUMPRODUCT(('ALL 498 CONSOLIDATED NEW'!$N$2:$N$503=A$1)*(A4='ALL 498 CONSOLIDATED NEW'!$K$2:$M$503)*(ISNUMBER(MATCH('ALL 498 CONSOLIDATED NEW'!$G$2:$G$503,Table1713141118[SCHOOL LIST],0))))} -> 2 | D4: 2 | E4: =C4-D4 -> 0 | F4: ND-03 | G4: 101103003 | H4: {=SUMPRODUCT(('ALL 498 CONSOLIDATED NEW'!$N$2:$N$503=F$1)*(F4='ALL 498 CONSOLIDATED NEW'!$K$2:$M$503)*(ISNUMBER(MATCH('ALL 498 CONSOLIDATED NEW'!$G$2:$G$503,Table1713141118[SCHOOL LIST],0))))} -> 2 | I4: 2 | J4: =H4-I4 -> 0 | K4: ND-03 | L4: 105101003 | M4: {=SUMPRODUCT(('ALL 498 CONSOLIDATED NEW'!$N$2:$N$503=K$1)*(K4='ALL 498 CONSOLIDATED NEW'!$K$2:$M$503)*(ISNUMBER(MATCH('ALL 498 CONSOLIDATED NEW'!$G$2:$G$503,Table1713141118[SCHOOL LIST],0))))} -> 4 | N4: 4 | O4: =M4-N4 -> 0 | AL4: PERINAD BUDS SCHOOL | AM4: 1 | AN4: Palm Pen Holder | AO4: =C22/3 -> 30
A5: ND-04 | B5: 302102004 | C5: {=SUMPRODUCT(('ALL 498 CONSOLIDATED NEW'!$N$2:$N$503=A$1)*(A5='ALL 498 CONSOLIDATED NEW'!$K$2:$M$503)*(ISNUMBER(MATCH('ALL 498 CONSOLIDATED NEW'!$G$2:$G$503,Table1713141118[SCHOOL LIST],0))))} -> 0 | D5: 0 | E5: =C5-D5 -> 0 | F5: ND-04 | G5: 101103004 | H5: {=SUMPRODUCT(('ALL 498 CONSOLIDATED NEW'!$N$2:$N$503=F$1)*(F5='ALL 498 CONSOLIDATED NEW'!$K$2:$M$503)*(ISNUMBER(MATCH('ALL 498 CONSOLIDATED NEW'!$G$2:$G$503,Table1713141118[SCHOOL LIST],0))))} -> 0 | I5: 0 | J5: =H5-I5 -> 0 | K5: ND-04 | L5: 105101004 | M5: {=SUMPRODUCT(('ALL 498 CONSOLIDATED NEW'!$N$2:$N$503=K$1)*(K5='ALL 498 CONSOLIDATED NEW'!$K$2:$M$503)*(ISNUMBER(MATCH('ALL 498 CONSOLIDATED NEW'!$G$2:$G$503,Table1713141118[SCHOOL LIST],0))))} -> 0 | N5: 0 | O5: =M5-N5 -> 0 | AL5: BODHINI BUDS SCHOOL | AM5: 2 | AN5: TOOTH BRUSH ADAPTER | AO5: =H22/3 -> 21
